<?xml version="1.0"?>
<robot name="DRCTestbedButton_static"
       xmlns:xi="http://www.w3.org/2001/XInclude"
       >
  <gazebo>
    <static>true</static>
  </gazebo>
  <link name="DRC-TESTBED-BUTTON-BODYSET9_link">
    <visual>
      <origin xyz="0 0 0" rpy="0 -0 0"/>
      <geometry>
        <mesh filename="model://DRCTestbedButton/meshes/DRC-TESTBED-BUTTON-BODYSET9_link_mesh.dae" scale="1 1 1" />
      </geometry>
    </visual>
    <collision>
      <origin xyz="0 0 0" rpy="0 -0 0"/>
      <geometry>
        <mesh filename="model://DRCTestbedButton/meshes/DRC-TESTBED-BUTTON-BODYSET9_link_mesh.dae" scale="1 1 1" />
      </geometry>
    </collision>
    <inertial>
      <mass value="0.001" />
      <origin xyz="0 0 0" rpy="0 -0 0"/>
      <inertia ixx="1e-03" ixy="0" ixz="0" iyy="1e-03" iyz="0" izz="1e-03"/>
    </inertial>
  </link>
  <gazebo reference="DRC-TESTBED-BUTTON-BODYSET9_link">
    <mu1>0.9</mu1>
    <mu2>0.9</mu2>
  </gazebo>
  <link name="DRC-TESTBED-BUTTON-BODYSET92_link">
    <visual>
      <origin xyz="-0.13 0.1 1.33" rpy="0 -0 0"/>
      <geometry>
        <mesh filename="model://DRCTestbedButton/meshes/DRC-TESTBED-BUTTON-BODYSET92_link_mesh.dae" scale="1 1 1" />
      </geometry>
    </visual>
    <collision>
      <origin xyz="-0.13 0.1 1.33" rpy="0 -0 0"/>
      <geometry>
        <mesh filename="model://DRCTestbedButton/meshes/DRC-TESTBED-BUTTON-BODYSET92_link_mesh.dae" scale="1 1 1" />
      </geometry>
    </collision>
    <inertial>
      <mass value="0.001" />
      <origin xyz="0 0 0" rpy="0 -0 0"/>
      <inertia ixx="1e-03" ixy="0" ixz="0" iyy="1e-03" iyz="0" izz="1e-03"/>
    </inertial>
  </link>
  <gazebo reference="DRC-TESTBED-BUTTON-BODYSET92_link">
    <mu1>0.9</mu1>
    <mu2>0.9</mu2>
  </gazebo>
  <joint name="HINGE-JOINT" type="revolute">
    <parent link="DRC-TESTBED-BUTTON-BODYSET9_link"/>
    <child  link="DRC-TESTBED-BUTTON-BODYSET92_link"/>
    <origin xyz="-0.13 0.1 1.33" rpy="0 -0 0 "/>
    <axis   xyz="0 0 1"/>
    <limit lower="-1.5708" upper="1.5708" effort="100" velocity="0.5" />
    <dynamics damping="0.2" friction="0" />
  </joint>
  <transmission type="pr2_mechanism_model/SimpleTransmission" name="HINGE-JOINT_trans" >
    <actuator name="HINGE-JOINT_motor" />
    <joint name="HINGE-JOINT" />
    <mechanicalReduction>1</mechanicalReduction>
  </transmission>
  <gazebo reference="HINGE-JOINT">
    <cfmDamping>0.4</cfmDamping>
  </gazebo>
</robot>
