<?xml version="1.0"?>
<robot name="LIP"
       xmlns:xi="http://www.w3.org/2001/XInclude"
       >
  <gazebo>
    <static>false</static>
  </gazebo>
  <link name="LINK0_link">
    <visual>
      <origin xyz="0 0 0" rpy="0 -0 0"/>
      <geometry>
        <mesh filename="model://LIP/meshes/LINK0_link_mesh.dae" scale="1 1 1" />
      </geometry>
    </visual>
    <collision>
      <origin xyz="0 0 0" rpy="0 -0 0"/>
      <geometry>
        <mesh filename="model://LIP/meshes/LINK0_link_mesh.dae" scale="1 1 1" />
      </geometry>
    </collision>
    <inertial>
      <mass value="100" />
      <origin xyz="0 0 0" rpy="0 -0 0"/>
      <inertia ixx="10" ixy="0" ixz="0" iyy="10" iyz="0" izz="10"/>
    </inertial>
  </link>
  <gazebo reference="LINK0_link">
    <mu1>100.0</mu1>
    <mu2>100.0</mu2>
  </gazebo>
  <link name="LINK1_link">
    <visual>
      <origin xyz="0 0 0.005" rpy="0 -0 0"/>
      <geometry>
        <mesh filename="model://LIP/meshes/LINK1_link_mesh.dae" scale="1 1 1" />
      </geometry>
    </visual>
    <collision>
      <origin xyz="0 0 0.005" rpy="0 -0 0"/>
      <geometry>
        <mesh filename="model://LIP/meshes/LINK1_link_mesh.dae" scale="1 1 1" />
      </geometry>
    </collision>
    <inertial>
      <mass value="0.0001" />
      <origin xyz="0 0 0" rpy="0 -0 0"/>
      <inertia ixx="1e-03" ixy="0" ixz="0" iyy="1e-03" iyz="0" izz="1e-03"/>
    </inertial>
  </link>
  <gazebo reference="LINK1_link">
    <mu1>0.9</mu1>
    <mu2>0.9</mu2>
  </gazebo>
  <link name="LINK2_link">
    <visual>
      <origin xyz="0 0 0" rpy="0 -0 0"/>
      <geometry>
        <mesh filename="model://LIP/meshes/LINK2_link_mesh.dae" scale="1 1 1" />
      </geometry>
    </visual>
    <collision>
      <origin xyz="0 0 0" rpy="0 -0 0"/>
      <geometry>
        <mesh filename="model://LIP/meshes/LINK2_link_mesh.dae" scale="1 1 1" />
      </geometry>
    </collision>
    <inertial>
      <mass value="0.0001" />
      <origin xyz="0 0 0" rpy="0 -0 0"/>
      <inertia ixx="1e-03" ixy="0" ixz="0" iyy="1e-03" iyz="0" izz="1e-03"/>
    </inertial>
  </link>
  <gazebo reference="LINK2_link">
    <mu1>0.9</mu1>
    <mu2>0.9</mu2>
  </gazebo>
  <link name="LINK3_link">
    <visual>
      <origin xyz="0 0 1" rpy="0 -0 0"/>
      <geometry>
        <mesh filename="model://LIP/meshes/LINK3_link_mesh.dae" scale="1 1 1" />
      </geometry>
    </visual>
    <collision>
      <origin xyz="0 0 1" rpy="0 -0 0"/>
      <geometry>
        <mesh filename="model://LIP/meshes/LINK3_link_mesh.dae" scale="1 1 1" />
      </geometry>
    </collision>
    <inertial>
      <mass value="0.0001" />
      <origin xyz="0 0 2.22045e-16" rpy="0 -0 0"/>
      <inertia ixx="1e-03" ixy="0" ixz="0" iyy="1e-03" iyz="0" izz="1e-03"/>
    </inertial>
  </link>
  <gazebo reference="LINK3_link">
    <mu1>0.9</mu1>
    <mu2>0.9</mu2>
  </gazebo>
  <link name="LINK4_link">
    <visual>
      <origin xyz="0 0 1" rpy="0 -0 0"/>
      <geometry>
        <mesh filename="model://LIP/meshes/LINK4_link_mesh.dae" scale="1 1 1" />
      </geometry>
    </visual>
    <collision>
      <origin xyz="0 0 1" rpy="0 -0 0"/>
      <geometry>
        <mesh filename="model://LIP/meshes/LINK4_link_mesh.dae" scale="1 1 1" />
      </geometry>
    </collision>
    <inertial>
      <mass value="1" />
      <origin xyz="0 0 0" rpy="0 -0 0"/>
      <inertia ixx="1e-03" ixy="0" ixz="0" iyy="1e-03" iyz="0" izz="1e-03"/>
    </inertial>
  </link>
  <gazebo reference="LINK4_link">
    <mu1>0.9</mu1>
    <mu2>0.9</mu2>
  </gazebo>
  <joint name="JOINT0" type="revolute">
    <parent link="LINK0_link"/>
    <child  link="LINK1_link"/>
    <origin xyz="0 0 0.005" rpy="0 -0 0 "/>
    <axis   xyz="1 0 0"/>
    <limit lower="-1.5708" upper="1.5708" effort="100" velocity="0.5" />
    <dynamics damping="0.2" friction="0" />
  </joint>
  <transmission type="pr2_mechanism_model/SimpleTransmission" name="JOINT0_trans" >
    <actuator name="JOINT0_motor" />
    <joint name="JOINT0" />
    <mechanicalReduction>1</mechanicalReduction>
  </transmission>
  <gazebo reference="JOINT0">
    <cfmDamping>0.4</cfmDamping>
  </gazebo>
  <joint name="JOINT1" type="revolute">
    <parent link="LINK1_link"/>
    <child  link="LINK2_link"/>
    <origin xyz="0 0 0" rpy="0 -0 0 "/>
    <axis   xyz="0 1 0"/>
    <limit lower="-1.5708" upper="1.5708" effort="100" velocity="0.5" />
    <dynamics damping="0.2" friction="0" />
  </joint>
  <transmission type="pr2_mechanism_model/SimpleTransmission" name="JOINT1_trans" >
    <actuator name="JOINT1_motor" />
    <joint name="JOINT1" />
    <mechanicalReduction>1</mechanicalReduction>
  </transmission>
  <gazebo reference="JOINT1">
    <cfmDamping>0.4</cfmDamping>
  </gazebo>
  <joint name="JOINT2" type="prismatic">
    <parent link="LINK2_link"/>
    <child  link="LINK3_link"/>
    <origin xyz="0 0 1" rpy="0 -0 0 "/>
    <axis   xyz="0 0 1"/>
    <limit lower="-1" upper="100" effort="100" velocity="1000" />
    <dynamics damping="0" friction="0" />
  </joint>
  <transmission type="pr2_mechanism_model/SimpleTransmission" name="JOINT2_trans" >
    <actuator name="JOINT2_motor" />
    <joint name="JOINT2" />
    <mechanicalReduction>1</mechanicalReduction>
  </transmission>
  <gazebo reference="JOINT2">
    <cfmDamping>0.4</cfmDamping>
  </gazebo>
  <joint name="JOINT3" type="prismatic">
    <parent link="LINK3_link"/>
    <child  link="LINK4_link"/>
    <origin xyz="0 0 1" rpy="0 -0 0 "/>
    <axis   xyz="0 0 1"/>
    <limit lower="0" upper="0" effort="100" velocity="0.5" />
    <dynamics damping="0.2" friction="0" />
  </joint>
  <transmission type="pr2_mechanism_model/SimpleTransmission" name="JOINT3_trans" >
    <actuator name="JOINT3_motor" />
    <joint name="JOINT3" />
    <mechanicalReduction>1</mechanicalReduction>
  </transmission>
  <gazebo reference="JOINT3">
    <cfmDamping>0.4</cfmDamping>
  </gazebo>
  <gazebo>
    <plugin filename="libLIPPlugin.so" name="LIPplugin" >
    </plugin>
  </gazebo>
</robot>
