<?xml version="1.0"?>
<robot name="DRCTestbedShower"
       xmlns:xi="http://www.w3.org/2001/XInclude"
       >
  <gazebo>
    <static>false</static>
  </gazebo>
  <link name="DRC-TESTBED-SHOWER-BODYSET9_link">
    <visual>
      <origin xyz="0 0 0" rpy="0 -0 0"/>
      <geometry>
        <mesh filename="model://DRCTestbedShower/meshes/DRC-TESTBED-SHOWER-BODYSET9_link_mesh.dae" scale="1 1 1" />
      </geometry>
    </visual>
    <collision>
      <origin xyz="0 0 0" rpy="0 -0 0"/>
      <geometry>
        <mesh filename="model://DRCTestbedShower/meshes/DRC-TESTBED-SHOWER-BODYSET9_link_mesh.dae" scale="1 1 1" />
      </geometry>
    </collision>
    <inertial>
      <mass value="0.001" />
      <origin xyz="0 0 0" rpy="0 -0 0"/>
      <inertia ixx="1e-03" ixy="0" ixz="0" iyy="1e-03" iyz="0" izz="1e-03"/>
    </inertial>
  </link>
  <gazebo reference="DRC-TESTBED-SHOWER-BODYSET9_link">
    <mu1>0.9</mu1>
    <mu2>0.9</mu2>
  </gazebo>
  <link name="DRC-TESTBED-SHOWER-BODYSET165_link">
    <visual>
      <origin xyz="-0.275 0.6 2.385" rpy="0 -0 0"/>
      <geometry>
        <mesh filename="model://DRCTestbedShower/meshes/DRC-TESTBED-SHOWER-BODYSET165_link_mesh.dae" scale="1 1 1" />
      </geometry>
    </visual>
    <collision>
      <origin xyz="-0.275 0.6 2.385" rpy="0 -0 0"/>
      <geometry>
        <mesh filename="model://DRCTestbedShower/meshes/DRC-TESTBED-SHOWER-BODYSET165_link_mesh.dae" scale="1 1 1" />
      </geometry>
    </collision>
    <inertial>
      <mass value="0.001" />
      <origin xyz="0 0 0" rpy="0 -0 0"/>
      <inertia ixx="1e-03" ixy="0" ixz="0" iyy="1e-03" iyz="0" izz="1e-03"/>
    </inertial>
  </link>
  <gazebo reference="DRC-TESTBED-SHOWER-BODYSET165_link">
    <mu1>0.9</mu1>
    <mu2>0.9</mu2>
  </gazebo>
  <link name="DRC-TESTBED-SHOWER-BODYSET186_link">
    <visual>
      <origin xyz="-0.19 0 0" rpy="0 -0 0"/>
      <geometry>
        <mesh filename="model://DRCTestbedShower/meshes/DRC-TESTBED-SHOWER-BODYSET186_link_mesh.dae" scale="1 1 1" />
      </geometry>
    </visual>
    <collision>
      <origin xyz="-0.19 0 0" rpy="0 -0 0"/>
      <geometry>
        <mesh filename="model://DRCTestbedShower/meshes/DRC-TESTBED-SHOWER-BODYSET186_link_mesh.dae" scale="1 1 1" />
      </geometry>
    </collision>
    <inertial>
      <mass value="0.001" />
      <origin xyz="0 0 0" rpy="0 -0 0"/>
      <inertia ixx="1e-03" ixy="0" ixz="0" iyy="1e-03" iyz="0" izz="1e-03"/>
    </inertial>
  </link>
  <gazebo reference="DRC-TESTBED-SHOWER-BODYSET186_link">
    <mu1>0.9</mu1>
    <mu2>0.9</mu2>
  </gazebo>
  <joint name="BAR1-JOINT" type="revolute">
    <parent link="DRC-TESTBED-SHOWER-BODYSET9_link"/>
    <child  link="DRC-TESTBED-SHOWER-BODYSET165_link"/>
    <origin xyz="-0.275 0.6 2.385" rpy="0 -0 0 "/>
    <axis   xyz="0 1 0"/>
    <limit lower="-1.5708" upper="1.5708" effort="100" velocity="0.5" />
    <dynamics damping="0.2" friction="0" />
  </joint>
  <transmission type="pr2_mechanism_model/SimpleTransmission" name="BAR1-JOINT_trans" >
    <actuator name="BAR1-JOINT_motor" />
    <joint name="BAR1-JOINT" />
    <mechanicalReduction>1</mechanicalReduction>
  </transmission>
  <gazebo reference="BAR1-JOINT">
    <cfmDamping>0.4</cfmDamping>
  </gazebo>
  <joint name="BAR2-JOINT" type="revolute">
    <parent link="DRC-TESTBED-SHOWER-BODYSET165_link"/>
    <child  link="DRC-TESTBED-SHOWER-BODYSET186_link"/>
    <origin xyz="-0.19 0 0" rpy="0 -0 0 "/>
    <axis   xyz="0 1 0"/>
    <limit lower="-1.5708" upper="1.5708" effort="100" velocity="0.5" />
    <dynamics damping="0.2" friction="0" />
  </joint>
  <transmission type="pr2_mechanism_model/SimpleTransmission" name="BAR2-JOINT_trans" >
    <actuator name="BAR2-JOINT_motor" />
    <joint name="BAR2-JOINT" />
    <mechanicalReduction>1</mechanicalReduction>
  </transmission>
  <gazebo reference="BAR2-JOINT">
    <cfmDamping>0.4</cfmDamping>
  </gazebo>
</robot>
