<?xml version="1.0" ?>
<!-- =================================================================================== -->
<!-- |    This document was autogenerated by xacro from HRP2JSKNTS.urdf.xacro          | -->
<!-- |    EDITING THIS FILE BY HAND IS NOT RECOMMENDED                                 | -->
<!-- =================================================================================== -->
<robot name="HRP2JSKNTS" xmlns:body="http://playerstage.sourceforge.net/gazebo/xmlschema/#body" xmlns:controller="http://playerstage.sourceforge.net/gazebo/xmlschema/#controller" xmlns:gazebo="http://playerstage.sourceforge.net/gazebo/xmlschema/#gz" xmlns:geom="http://playerstage.sourceforge.net/gazebo/xmlschema/#geom" xmlns:interface="http://playerstage.sourceforge.net/gazebo/xmlschema/#interface" xmlns:joint="http://playerstage.sourceforge.net/gazebo/xmlschema/#joint" xmlns:model="http://playerstage.sourceforge.net/gazebo/xmlschema/#model" xmlns:physics="http://playerstage.sourceforge.net/gazebo/xmlschema/#physics" xmlns:renderable="http://playerstage.sourceforge.net/gazebo/xmlschema/#renderable" xmlns:rendering="http://playerstage.sourceforge.net/gazebo/xmlschema/#rendering" xmlns:sensor="http://playerstage.sourceforge.net/gazebo/xmlschema/#sensor" xmlns:xacro="http://www.ros.org/wiki/xacro" xmlns:xi="http://www.w3.org/2001/XInclude">
  <link name="BODY">
    <visual>
      <origin rpy="0 -0 0" xyz="0 0 0.705"/>
      <geometry>
        <mesh filename="package://hrpsys_ros_bridge_tutorials/models/HRP2JSKNTS_meshes/BODY_mesh.dae" scale="1 1 1"/>
      </geometry>
    </visual>
    <collision>
      <origin rpy="0 -0 0" xyz="0 0 0.705"/>
      <geometry>
        <mesh filename="package://hrpsys_ros_bridge_tutorials/models/HRP2JSKNTS_meshes/BODY_mesh.dae" scale="1 1 1"/>
      </geometry>
    </collision>
    <inertial>
      <mass value="15.0295"/>
      <origin rpy="0 -0 0" xyz="-0.0143514 1.2e-07 0.220077"/>
      <inertia ixx="0.161026" ixy="-2.6504e-07" ixz="0.000706962" iyy="0.09528" iyz="-1.95085e-07" izz="0.191914"/>
    </inertial>
  </link>
  <gazebo reference="BODY">
    <mu1>0.9</mu1>
    <mu2>0.9</mu2>
  </gazebo>
  <link name="CHEST_LINK0">
    <visual>
      <origin rpy="0 -0 0" xyz="0.032 0 0.3507"/>
      <geometry>
        <mesh filename="package://hrpsys_ros_bridge_tutorials/models/HRP2JSKNTS_meshes/CHEST_LINK0_mesh.dae" scale="1 1 1"/>
      </geometry>
    </visual>
    <collision>
      <origin rpy="0 -0 0" xyz="0.032 0 0.3507"/>
      <geometry>
        <mesh filename="package://hrpsys_ros_bridge_tutorials/models/HRP2JSKNTS_meshes/CHEST_LINK0_mesh.dae" scale="1 1 1"/>
      </geometry>
    </collision>
    <inertial>
      <mass value="0.786369"/>
      <origin rpy="0 -0 0" xyz="-0.0158016 0.00529544 -0.0251963"/>
      <inertia ixx="0.00181617" ixy="-7.322e-05" ixz="-0.00027731" iyy="0.00185079" iyz="-0.00010749" izz="0.00233207"/>
    </inertial>
  </link>
  <gazebo reference="CHEST_LINK0">
    <mu1>0.9</mu1>
    <mu2>0.9</mu2>
  </gazebo>
  <link name="CHEST_LINK1">
    <visual>
      <origin rpy="0 -0 0" xyz="0 0 0"/>
      <geometry>
        <mesh filename="package://hrpsys_ros_bridge_tutorials/models/HRP2JSKNTS_meshes/CHEST_LINK1_mesh.dae" scale="1 1 1"/>
      </geometry>
    </visual>
    <collision>
      <origin rpy="0 -0 0" xyz="0 0 0"/>
      <geometry>
        <mesh filename="package://hrpsys_ros_bridge_tutorials/models/HRP2JSKNTS_meshes/CHEST_LINK1_mesh.dae" scale="1 1 1"/>
      </geometry>
    </collision>
    <inertial>
      <mass value="11.5246"/>
      <origin rpy="0 -0 0" xyz="-0.0290496 0.00716411 0.121025"/>
      <inertia ixx="0.160476" ixy="-0.00135932" ixz="-0.00414493" iyy="0.136846" iyz="0.00388036" izz="0.181669"/>
    </inertial>
  </link>
  <gazebo reference="CHEST_LINK1">
    <mu1>0.9</mu1>
    <mu2>0.9</mu2>
  </gazebo>
  <link name="HEAD_LINK0">
    <visual>
      <origin rpy="0 -0 0" xyz="-0.007 0 0.2973"/>
      <geometry>
        <mesh filename="package://hrpsys_ros_bridge_tutorials/models/HRP2JSKNTS_meshes/HEAD_LINK0_mesh.dae" scale="1 1 1"/>
      </geometry>
    </visual>
    <collision>
      <origin rpy="0 -0 0" xyz="-0.007 0 0.2973"/>
      <geometry>
        <mesh filename="package://hrpsys_ros_bridge_tutorials/models/HRP2JSKNTS_meshes/HEAD_LINK0_mesh.dae" scale="1 1 1"/>
      </geometry>
    </collision>
    <inertial>
      <mass value="0.362181"/>
      <origin rpy="0 -0 0" xyz="-0.00090801 0.00274824 -0.00825901"/>
      <inertia ixx="0.00038285" ixy="-5.2e-07" ixz="2.24e-06" iyy="0.00021609" iyz="-7.26e-06" izz="0.0003473"/>
    </inertial>
  </link>
  <gazebo reference="HEAD_LINK0">
    <mu1>0.9</mu1>
    <mu2>0.9</mu2>
  </gazebo>
  <link name="HEAD_LINK1">
    <visual>
      <origin rpy="1.75 0 1.57" xyz="0.03 0 0.19"/>
      <geometry>
        <!-- <mesh filename="package://hrpsys_ros_bridge_tutorials/models/HRP2JSKNTS_meshes/HEAD_LINK1_mesh.dae" scale="1 1 1"/> -->
        <mesh filename="package://hrpsys_ros_bridge_tutorials/models/HRP2JSKNTS_meshes/HEAD_MULTISENSE_CUT.stl" scale="0.001 0.001 0.001"/>
      </geometry>
      <material name="gray">
        <color rgba="0.5 0.5 0.5 1"/>
      </material>
    </visual>
    <collision>
      <origin rpy="0 -0 0" xyz="0 0 0"/>
      <geometry>
        <!-- <mesh filename="package://hrpsys_ros_bridge_tutorials/models/HRP2JSKNTS_meshes/HEAD_LINK1_mesh.dae" scale="1 1 1"/> -->
        <mesh filename="package://hrpsys_ros_bridge_tutorials/models/HRP2JSKNTS_meshes/HEAD_MULTISENSE_CUT.stl" scale="0.001 0.001 0.001"/>
      </geometry>
    </collision>
    <inertial>
      <mass value="0.921545"/>
      <origin rpy="0 -0 0" xyz="0.00900923 -0.00054084 0.0888815"/>
      <inertia ixx="0.00393357" ixy="4.68e-06" ixz="7.928e-05" iyy="0.00413822" iyz="-9.051e-05" izz="0.00524469"/>
    </inertial>
  </link>
  <gazebo reference="HEAD_LINK1">
    <mu1>0.9</mu1>
    <mu2>0.9</mu2>
  </gazebo>
  <link name="LARM_LINK0">
    <visual>
      <origin rpy="0 -0 0" xyz="0.008 0.28 0.181"/>
      <geometry>
        <mesh filename="package://hrpsys_ros_bridge_tutorials/models/HRP2JSKNTS_meshes/LARM_LINK0_mesh.dae" scale="1 1 1"/>
      </geometry>
    </visual>
    <collision>
      <origin rpy="0 -0 0" xyz="0.008 0.28 0.181"/>
      <geometry>
        <mesh filename="package://hrpsys_ros_bridge_tutorials/models/HRP2JSKNTS_meshes/LARM_LINK0_mesh.dae" scale="1 1 1"/>
      </geometry>
    </collision>
    <inertial>
      <mass value="0.810076"/>
      <origin rpy="0 -0 0" xyz="-0.00989448 -0.0464526 -0.00015316"/>
      <inertia ixx="0.00221115" ixy="0.00030424" ixz="1.47e-06" iyy="0.00184189" iyz="-4.667e-05" izz="0.00344772"/>
    </inertial>
  </link>
  <gazebo reference="LARM_LINK0">
    <mu1>0.9</mu1>
    <mu2>0.9</mu2>
  </gazebo>
  <link name="LARM_LINK1">
    <visual>
      <origin rpy="0 -0 0" xyz="0 0 0"/>
      <geometry>
        <mesh filename="package://hrpsys_ros_bridge_tutorials/models/HRP2JSKNTS_meshes/LARM_LINK1_mesh.dae" scale="1 1 1"/>
      </geometry>
    </visual>
    <collision>
      <origin rpy="0 -0 0" xyz="0 0 0"/>
      <geometry>
        <mesh filename="package://hrpsys_ros_bridge_tutorials/models/HRP2JSKNTS_meshes/LARM_LINK1_mesh.dae" scale="1 1 1"/>
      </geometry>
    </collision>
    <inertial>
      <mass value="1.03448"/>
      <origin rpy="0 -0 0" xyz="-0.0105646 0.0120429 -0.00948156"/>
      <inertia ixx="0.00122098" ixy="-0.00028119" ixz="9.407e-05" iyy="0.00172216" iyz="-0.00012041" izz="0.00161319"/>
    </inertial>
  </link>
  <gazebo reference="LARM_LINK1">
    <mu1>0.9</mu1>
    <mu2>0.9</mu2>
  </gazebo>
  <link name="LARM_LINK2">
    <visual>
      <origin rpy="0 -0 0" xyz="0 0 0"/>
      <geometry>
        <mesh filename="package://hrpsys_ros_bridge_tutorials/models/HRP2JSKNTS_meshes/LARM_LINK2_mesh.dae" scale="1 1 1"/>
      </geometry>
    </visual>
    <collision>
      <origin rpy="0 -0 0" xyz="0 0 0"/>
      <geometry>
        <mesh filename="package://hrpsys_ros_bridge_tutorials/models/HRP2JSKNTS_meshes/LARM_LINK2_mesh.dae" scale="1 1 1"/>
      </geometry>
    </collision>
    <inertial>
      <mass value="1.59929"/>
      <origin rpy="0 -0 0" xyz="-0.00543072 0.00479797 -0.166872"/>
      <inertia ixx="0.00973049" ixy="5.13304e-05" ixz="-0.000199167" iyy="0.00970372" iyz="-0.000137469" izz="0.00135331"/>
    </inertial>
  </link>
  <gazebo reference="LARM_LINK2">
    <mu1>0.9</mu1>
    <mu2>0.9</mu2>
  </gazebo>
  <link name="LARM_LINK3">
    <visual>
      <origin rpy="0 -0 0" xyz="0 0 -0.25"/>
      <geometry>
        <mesh filename="package://hrpsys_ros_bridge_tutorials/models/HRP2JSKNTS_meshes/LARM_LINK3_mesh.dae" scale="1 1 1"/>
      </geometry>
    </visual>
    <collision>
      <origin rpy="0 -0 0" xyz="0 0 -0.25"/>
      <geometry>
        <mesh filename="package://hrpsys_ros_bridge_tutorials/models/HRP2JSKNTS_meshes/LARM_LINK3_mesh.dae" scale="1 1 1"/>
      </geometry>
    </collision>
    <inertial>
      <mass value="0.77725"/>
      <origin rpy="0 -0 0" xyz="-9.27e-06 0.0161684 -0.0627015"/>
      <inertia ixx="0.00232668" ixy="-7e-08" ixz="-3.1e-07" iyy="0.00212476" iyz="-0.00015097" izz="0.00056363"/>
    </inertial>
  </link>
  <gazebo reference="LARM_LINK3">
    <mu1>0.9</mu1>
    <mu2>0.9</mu2>
  </gazebo>
  <link name="LARM_LINK4">
    <visual>
      <origin rpy="0 -0 0" xyz="0 0 -0.25"/>
      <geometry>
        <mesh filename="package://hrpsys_ros_bridge_tutorials/models/HRP2JSKNTS_meshes/LARM_LINK4_mesh.dae" scale="1 1 1"/>
      </geometry>
    </visual>
    <collision>
      <origin rpy="0 -0 0" xyz="0 0 -0.25"/>
      <geometry>
        <mesh filename="package://hrpsys_ros_bridge_tutorials/models/HRP2JSKNTS_meshes/LARM_LINK4_mesh.dae" scale="1 1 1"/>
      </geometry>
    </collision>
    <inertial>
      <mass value="0.328543"/>
      <origin rpy="0 -0 0" xyz="-0.00840122 -1.406e-05 0.0472199"/>
      <inertia ixx="0.00084438" ixy="4e-08" ixz="-0.00013812" iyy="0.00105692" iyz="2.3e-07" izz="0.00034468"/>
    </inertial>
  </link>
  <gazebo reference="LARM_LINK4">
    <mu1>0.9</mu1>
    <mu2>0.9</mu2>
  </gazebo>
  <link name="LARM_LINK5">
    <visual>
      <origin rpy="0 -0 0" xyz="0 0 0"/>
      <geometry>
        <mesh filename="package://hrpsys_ros_bridge_tutorials/models/HRP2JSKNTS_meshes/LARM_LINK5_mesh.dae" scale="1 1 1"/>
      </geometry>
    </visual>
    <collision>
      <origin rpy="0 -0 0" xyz="0 0 0"/>
      <geometry>
        <mesh filename="package://hrpsys_ros_bridge_tutorials/models/HRP2JSKNTS_meshes/LARM_LINK5_mesh.dae" scale="1 1 1"/>
      </geometry>
    </collision>
    <inertial>
      <mass value="0.460767"/>
      <origin rpy="0 -0 0" xyz="0.00361678 0.00180569 -0.00656872"/>
      <inertia ixx="0.00026432" ixy="3.17e-06" ixz="-1.177e-05" iyy="0.0002938" iyz="-1.08e-05" izz="0.0002986"/>
    </inertial>
  </link>
  <gazebo reference="LARM_LINK5">
    <mu1>0.9</mu1>
    <mu2>0.9</mu2>
  </gazebo>
  <link name="LARM_LINK7">
    <visual>
      <origin rpy="0 -0 0" xyz="0 -0.0169 -0.114"/>
      <geometry>
        <mesh filename="package://hrpsys_ros_bridge_tutorials/models/HRP2JSKNTS_meshes/LARM_LINK7_mesh.dae" scale="1 1 1"/>
      </geometry>
    </visual>
    <collision>
      <origin rpy="0 -0 0" xyz="0 -0.0169 -0.114"/>
      <geometry>
        <mesh filename="package://hrpsys_ros_bridge_tutorials/models/HRP2JSKNTS_meshes/LARM_LINK7_mesh.dae" scale="1 1 1"/>
      </geometry>
    </collision>
    <inertial>
      <mass value="0"/>
      <origin rpy="0 -0 0" xyz="0 0 9.71445e-17"/>
      <inertia ixx="0" ixy="0" ixz="0" iyy="0" iyz="0" izz="0"/>
    </inertial>
  </link>
  <gazebo reference="LARM_LINK7">
    <mu1>0.9</mu1>
    <mu2>0.9</mu2>
  </gazebo>
  <link name="RARM_LINK0">
    <visual>
      <origin rpy="0 -0 0" xyz="0.008 -0.28 0.181"/>
      <geometry>
        <mesh filename="package://hrpsys_ros_bridge_tutorials/models/HRP2JSKNTS_meshes/RARM_LINK0_mesh.dae" scale="1 1 1"/>
      </geometry>
    </visual>
    <collision>
      <origin rpy="0 -0 0" xyz="0.008 -0.28 0.181"/>
      <geometry>
        <mesh filename="package://hrpsys_ros_bridge_tutorials/models/HRP2JSKNTS_meshes/RARM_LINK0_mesh.dae" scale="1 1 1"/>
      </geometry>
    </collision>
    <inertial>
      <mass value="0.810076"/>
      <origin rpy="0 -0 0" xyz="-0.00989448 0.0464526 -0.00015316"/>
      <inertia ixx="0.00221115" ixy="-0.00030424" ixz="1.47e-06" iyy="0.00184189" iyz="4.667e-05" izz="0.00344772"/>
    </inertial>
  </link>
  <gazebo reference="RARM_LINK0">
    <mu1>0.9</mu1>
    <mu2>0.9</mu2>
  </gazebo>
  <link name="RARM_LINK1">
    <visual>
      <origin rpy="0 -0 0" xyz="0 0 0"/>
      <geometry>
        <mesh filename="package://hrpsys_ros_bridge_tutorials/models/HRP2JSKNTS_meshes/RARM_LINK1_mesh.dae" scale="1 1 1"/>
      </geometry>
    </visual>
    <collision>
      <origin rpy="0 -0 0" xyz="0 0 0"/>
      <geometry>
        <mesh filename="package://hrpsys_ros_bridge_tutorials/models/HRP2JSKNTS_meshes/RARM_LINK1_mesh.dae" scale="1 1 1"/>
      </geometry>
    </collision>
    <inertial>
      <mass value="1.03448"/>
      <origin rpy="0 -0 0" xyz="-0.0105646 -0.0120429 -0.00948156"/>
      <inertia ixx="0.00122098" ixy="0.00028119" ixz="9.407e-05" iyy="0.00172216" iyz="0.00012041" izz="0.00161319"/>
    </inertial>
  </link>
  <gazebo reference="RARM_LINK1">
    <mu1>0.9</mu1>
    <mu2>0.9</mu2>
  </gazebo>
  <link name="RARM_LINK2">
    <visual>
      <origin rpy="0 -0 0" xyz="0 0 0"/>
      <geometry>
        <mesh filename="package://hrpsys_ros_bridge_tutorials/models/HRP2JSKNTS_meshes/RARM_LINK2_mesh.dae" scale="1 1 1"/>
      </geometry>
    </visual>
    <collision>
      <origin rpy="0 -0 0" xyz="0 0 0"/>
      <geometry>
        <mesh filename="package://hrpsys_ros_bridge_tutorials/models/HRP2JSKNTS_meshes/RARM_LINK2_mesh.dae" scale="1 1 1"/>
      </geometry>
    </collision>
    <inertial>
      <mass value="1.59929"/>
      <origin rpy="0 -0 0" xyz="-0.00543072 -0.00479797 -0.166872"/>
      <inertia ixx="0.00973049" ixy="-5.13304e-05" ixz="-0.000199167" iyy="0.00970372" iyz="0.000137469" izz="0.00135331"/>
    </inertial>
  </link>
  <gazebo reference="RARM_LINK2">
    <mu1>0.9</mu1>
    <mu2>0.9</mu2>
  </gazebo>
  <link name="RARM_LINK3">
    <visual>
      <origin rpy="0 -0 0" xyz="0 0 -0.25"/>
      <geometry>
        <mesh filename="package://hrpsys_ros_bridge_tutorials/models/HRP2JSKNTS_meshes/RARM_LINK3_mesh.dae" scale="1 1 1"/>
      </geometry>
    </visual>
    <collision>
      <origin rpy="0 -0 0" xyz="0 0 -0.25"/>
      <geometry>
        <mesh filename="package://hrpsys_ros_bridge_tutorials/models/HRP2JSKNTS_meshes/RARM_LINK3_mesh.dae" scale="1 1 1"/>
      </geometry>
    </collision>
    <inertial>
      <mass value="0.77725"/>
      <origin rpy="0 -0 0" xyz="-9.27e-06 -0.0161684 -0.0627015"/>
      <inertia ixx="0.00232668" ixy="7e-08" ixz="-3.1e-07" iyy="0.00212476" iyz="0.00015097" izz="0.00056363"/>
    </inertial>
  </link>
  <gazebo reference="RARM_LINK3">
    <mu1>0.9</mu1>
    <mu2>0.9</mu2>
  </gazebo>
  <link name="RARM_LINK4">
    <visual>
      <origin rpy="0 -0 0" xyz="0 0 -0.25"/>
      <geometry>
        <mesh filename="package://hrpsys_ros_bridge_tutorials/models/HRP2JSKNTS_meshes/RARM_LINK4_mesh.dae" scale="1 1 1"/>
      </geometry>
    </visual>
    <collision>
      <origin rpy="0 -0 0" xyz="0 0 -0.25"/>
      <geometry>
        <mesh filename="package://hrpsys_ros_bridge_tutorials/models/HRP2JSKNTS_meshes/RARM_LINK4_mesh.dae" scale="1 1 1"/>
      </geometry>
    </collision>
    <inertial>
      <mass value="0.328543"/>
      <origin rpy="0 -0 0" xyz="-0.00840122 1.406e-05 0.0472199"/>
      <inertia ixx="0.00084438" ixy="-4e-08" ixz="-0.00013812" iyy="0.00105692" iyz="-2.3e-07" izz="0.00034468"/>
    </inertial>
  </link>
  <gazebo reference="RARM_LINK4">
    <mu1>0.9</mu1>
    <mu2>0.9</mu2>
  </gazebo>
  <link name="RARM_LINK5">
    <visual>
      <origin rpy="0 -0 0" xyz="0 0 0"/>
      <geometry>
        <mesh filename="package://hrpsys_ros_bridge_tutorials/models/HRP2JSKNTS_meshes/RARM_LINK5_mesh.dae" scale="1 1 1"/>
      </geometry>
    </visual>
    <collision>
      <origin rpy="0 -0 0" xyz="0 0 0"/>
      <geometry>
        <mesh filename="package://hrpsys_ros_bridge_tutorials/models/HRP2JSKNTS_meshes/RARM_LINK5_mesh.dae" scale="1 1 1"/>
      </geometry>
    </collision>
    <inertial>
      <mass value="0.460767"/>
      <origin rpy="0 -0 0" xyz="0.00361678 -0.00180569 -0.00656872"/>
      <inertia ixx="0.00026432" ixy="-3.17e-06" ixz="-1.177e-05" iyy="0.0002938" iyz="1.08e-05" izz="0.0002986"/>
    </inertial>
  </link>
  <gazebo reference="RARM_LINK5">
    <mu1>0.9</mu1>
    <mu2>0.9</mu2>
  </gazebo>
  <link name="RARM_LINK7">
    <visual>
      <origin rpy="0 -0 0" xyz="0 0.0169 -0.114"/>
      <geometry>
        <mesh filename="package://hrpsys_ros_bridge_tutorials/models/HRP2JSKNTS_meshes/RARM_LINK7_mesh.dae" scale="1 1 1"/>
      </geometry>
    </visual>
    <collision>
      <origin rpy="0 -0 0" xyz="0 0.0169 -0.114"/>
      <geometry>
        <mesh filename="package://hrpsys_ros_bridge_tutorials/models/HRP2JSKNTS_meshes/RARM_LINK7_mesh.dae" scale="1 1 1"/>
      </geometry>
    </collision>
    <inertial>
      <mass value="0"/>
      <origin rpy="0 -0 0" xyz="0 0 9.71445e-17"/>
      <inertia ixx="0" ixy="0" ixz="0" iyy="0" iyz="0" izz="0"/>
    </inertial>
  </link>
  <gazebo reference="RARM_LINK7">
    <mu1>0.9</mu1>
    <mu2>0.9</mu2>
  </gazebo>
  <link name="LLEG_LINK0">
    <visual>
      <origin rpy="0 -0 0" xyz="0 0.06 0"/>
      <geometry>
        <mesh filename="package://hrpsys_ros_bridge_tutorials/models/HRP2JSKNTS_meshes/LLEG_LINK0_mesh.dae" scale="1 1 1"/>
      </geometry>
    </visual>
    <collision>
      <origin rpy="0 -0 0" xyz="0 0.06 0"/>
      <geometry>
        <mesh filename="package://hrpsys_ros_bridge_tutorials/models/HRP2JSKNTS_meshes/LLEG_LINK0_mesh.dae" scale="1 1 1"/>
      </geometry>
    </collision>
    <inertial>
      <mass value="1.16852"/>
      <origin rpy="0 -0 0" xyz="-0.0103793 -0.00484329 0.0649015"/>
      <inertia ixx="0.00285998" ixy="1.43424e-05" ixz="-0.000555819" iyy="0.00352974" iyz="-8.84038e-06" izz="0.00145427"/>
    </inertial>
  </link>
  <gazebo reference="LLEG_LINK0">
    <mu1>0.9</mu1>
    <mu2>0.9</mu2>
  </gazebo>
  <link name="LLEG_LINK1">
    <visual>
      <origin rpy="0 -0 0" xyz="0 0 0"/>
      <geometry>
        <mesh filename="package://hrpsys_ros_bridge_tutorials/models/HRP2JSKNTS_meshes/LLEG_LINK1_mesh.dae" scale="1 1 1"/>
      </geometry>
    </visual>
    <collision>
      <origin rpy="0 -0 0" xyz="0 0 0"/>
      <geometry>
        <mesh filename="package://hrpsys_ros_bridge_tutorials/models/HRP2JSKNTS_meshes/LLEG_LINK1_mesh.dae" scale="1 1 1"/>
      </geometry>
    </collision>
    <inertial>
      <mass value="0.80553"/>
      <origin rpy="0 -0 0" xyz="-0.00039826 0.0261287 -0.00292156"/>
      <inertia ixx="0.00126683" ixy="-1.211e-05" ixz="1.64e-06" iyy="0.00050656" iyz="-6.938e-05" izz="0.00132021"/>
    </inertial>
  </link>
  <gazebo reference="LLEG_LINK1">
    <mu1>0.9</mu1>
    <mu2>0.9</mu2>
  </gazebo>
  <link name="LLEG_LINK2">
    <visual>
      <origin rpy="0 -0 0" xyz="0 0 0"/>
      <geometry>
        <mesh filename="package://hrpsys_ros_bridge_tutorials/models/HRP2JSKNTS_meshes/LLEG_LINK2_mesh.dae" scale="1 1 1"/>
      </geometry>
    </visual>
    <collision>
      <origin rpy="0 -0 0" xyz="0 0 0"/>
      <geometry>
        <mesh filename="package://hrpsys_ros_bridge_tutorials/models/HRP2JSKNTS_meshes/LLEG_LINK2_mesh.dae" scale="1 1 1"/>
      </geometry>
    </collision>
    <inertial>
      <mass value="2.07632"/>
      <origin rpy="0 -0 0" xyz="0.00345946 0.0779422 -0.151684"/>
      <inertia ixx="0.0261976" ixy="3.95406e-05" ixz="0.000573517" iyy="0.0249235" iyz="-0.000670077" izz="0.00376439"/>
    </inertial>
  </link>
  <gazebo reference="LLEG_LINK2">
    <mu1>0.9</mu1>
    <mu2>0.9</mu2>
  </gazebo>
  <link name="LLEG_LINK3">
    <visual>
      <origin rpy="0 -0 0" xyz="0 0 -0.3"/>
      <geometry>
        <mesh filename="package://hrpsys_ros_bridge_tutorials/models/HRP2JSKNTS_meshes/LLEG_LINK3_mesh.dae" scale="1 1 1"/>
      </geometry>
    </visual>
    <collision>
      <origin rpy="0 -0 0" xyz="0 0 -0.3"/>
      <geometry>
        <mesh filename="package://hrpsys_ros_bridge_tutorials/models/HRP2JSKNTS_meshes/LLEG_LINK3_mesh.dae" scale="1 1 1"/>
      </geometry>
    </collision>
    <inertial>
      <mass value="1.74762"/>
      <origin rpy="0 -0 0" xyz="0.0179878 0.0579164 -0.13839"/>
      <inertia ixx="0.0223269" ixy="9.39152e-05" ixz="-0.00224766" iyy="0.022506" iyz="0.000745178" izz="0.0045544"/>
    </inertial>
  </link>
  <gazebo reference="LLEG_LINK3">
    <mu1>0.9</mu1>
    <mu2>0.9</mu2>
  </gazebo>
  <link name="LLEG_LINK4">
    <visual>
      <origin rpy="0 -0 0" xyz="0 0.035 -0.3"/>
      <geometry>
        <mesh filename="package://hrpsys_ros_bridge_tutorials/models/HRP2JSKNTS_meshes/LLEG_LINK4_mesh.dae" scale="1 1 1"/>
      </geometry>
    </visual>
    <collision>
      <origin rpy="0 -0 0" xyz="0 0.035 -0.3"/>
      <geometry>
        <mesh filename="package://hrpsys_ros_bridge_tutorials/models/HRP2JSKNTS_meshes/LLEG_LINK4_mesh.dae" scale="1 1 1"/>
      </geometry>
    </collision>
    <inertial>
      <mass value="0.65375"/>
      <origin rpy="0 -0 0" xyz="0.00827083 0.00133301 -0.002418"/>
      <inertia ixx="0.00027773" ixy="5.26e-06" ixz="1.354e-05" iyy="0.00078966" iyz="3.59e-06" izz="0.00086039"/>
    </inertial>
  </link>
  <gazebo reference="LLEG_LINK4">
    <mu1>0.9</mu1>
    <mu2>0.9</mu2>
  </gazebo>
  <link name="LLEG_LINK5">
    <visual>
      <origin rpy="0 -0 0" xyz="0 0 0"/>
      <geometry>
        <mesh filename="package://hrpsys_ros_bridge_tutorials/models/HRP2JSKNTS_meshes/LLEG_LINK5_mesh.dae" scale="1 1 1"/>
      </geometry>
    </visual>
    <collision>
      <origin rpy="0 -0 0" xyz="0 0 0"/>
      <geometry>
        <mesh filename="package://hrpsys_ros_bridge_tutorials/models/HRP2JSKNTS_meshes/LLEG_LINK5_mesh.dae" scale="1 1 1"/>
      </geometry>
    </collision>
    <inertial>
      <mass value="1.63877"/>
      <origin rpy="0 -0 0" xyz="-0.00066419 0.00468922 -0.0653813"/>
      <inertia ixx="0.00400076" ixy="-9.983e-05" ixz="0.00079295" iyy="0.00687611" iyz="0.00018541" izz="0.00711516"/>
    </inertial>
  </link>
  <gazebo reference="LLEG_LINK5">
    <mu1>0.9</mu1>
    <mu2>0.9</mu2>
  </gazebo>
  <link name="LLEG_LINK6">
    <visual>
      <origin rpy="0 -0 0" xyz="0.115 0 -0.074"/>
      <geometry>
        <mesh filename="package://hrpsys_ros_bridge_tutorials/models/HRP2JSKNTS_meshes/LLEG_LINK6_mesh.dae" scale="1 1 1"/>
      </geometry>
    </visual>
    <collision>
      <origin rpy="0 -0 0" xyz="0.115 0 -0.074"/>
      <geometry>
        <mesh filename="package://hrpsys_ros_bridge_tutorials/models/HRP2JSKNTS_meshes/LLEG_LINK6_mesh.dae" scale="1 1 1"/>
      </geometry>
    </collision>
    <inertial>
      <mass value="0.509152"/>
      <origin rpy="0 -0 0" xyz="0.0199389 0.00614537 -0.0104375"/>
      <inertia ixx="0.00076266" ixy="2.741e-05" ixz="2.69e-06" iyy="0.00035733" iyz="1.182e-05" izz="0.00095164"/>
    </inertial>
  </link>
  <gazebo reference="LLEG_LINK6">
    <mu1>0.9</mu1>
    <mu2>0.9</mu2>
  </gazebo>
  <link name="RLEG_LINK0">
    <visual>
      <origin rpy="0 -0 0" xyz="0 -0.06 0"/>
      <geometry>
        <mesh filename="package://hrpsys_ros_bridge_tutorials/models/HRP2JSKNTS_meshes/RLEG_LINK0_mesh.dae" scale="1 1 1"/>
      </geometry>
    </visual>
    <collision>
      <origin rpy="0 -0 0" xyz="0 -0.06 0"/>
      <geometry>
        <mesh filename="package://hrpsys_ros_bridge_tutorials/models/HRP2JSKNTS_meshes/RLEG_LINK0_mesh.dae" scale="1 1 1"/>
      </geometry>
    </collision>
    <inertial>
      <mass value="1.16852"/>
      <origin rpy="0 -0 0" xyz="-0.0103793 0.00484329 0.0649015"/>
      <inertia ixx="0.00285998" ixy="-1.43424e-05" ixz="-0.000555819" iyy="0.00352974" iyz="8.84038e-06" izz="0.00145427"/>
    </inertial>
  </link>
  <gazebo reference="RLEG_LINK0">
    <mu1>0.9</mu1>
    <mu2>0.9</mu2>
  </gazebo>
  <link name="RLEG_LINK1">
    <visual>
      <origin rpy="0 -0 0" xyz="0 0 0"/>
      <geometry>
        <mesh filename="package://hrpsys_ros_bridge_tutorials/models/HRP2JSKNTS_meshes/RLEG_LINK1_mesh.dae" scale="1 1 1"/>
      </geometry>
    </visual>
    <collision>
      <origin rpy="0 -0 0" xyz="0 0 0"/>
      <geometry>
        <mesh filename="package://hrpsys_ros_bridge_tutorials/models/HRP2JSKNTS_meshes/RLEG_LINK1_mesh.dae" scale="1 1 1"/>
      </geometry>
    </collision>
    <inertial>
      <mass value="0.80553"/>
      <origin rpy="0 -0 0" xyz="-0.00039826 -0.0261287 -0.00292156"/>
      <inertia ixx="0.00126683" ixy="1.211e-05" ixz="1.64e-06" iyy="0.00050656" iyz="6.938e-05" izz="0.00132021"/>
    </inertial>
  </link>
  <gazebo reference="RLEG_LINK1">
    <mu1>0.9</mu1>
    <mu2>0.9</mu2>
  </gazebo>
  <link name="RLEG_LINK2">
    <visual>
      <origin rpy="0 -0 0" xyz="0 0 0"/>
      <geometry>
        <mesh filename="package://hrpsys_ros_bridge_tutorials/models/HRP2JSKNTS_meshes/RLEG_LINK2_mesh.dae" scale="1 1 1"/>
      </geometry>
    </visual>
    <collision>
      <origin rpy="0 -0 0" xyz="0 0 0"/>
      <geometry>
        <mesh filename="package://hrpsys_ros_bridge_tutorials/models/HRP2JSKNTS_meshes/RLEG_LINK2_mesh.dae" scale="1 1 1"/>
      </geometry>
    </collision>
    <inertial>
      <mass value="2.07632"/>
      <origin rpy="0 -0 0" xyz="0.00345946 -0.0779422 -0.151684"/>
      <inertia ixx="0.0261976" ixy="-3.95406e-05" ixz="0.000573517" iyy="0.0249235" iyz="0.000670077" izz="0.00376439"/>
    </inertial>
  </link>
  <gazebo reference="RLEG_LINK2">
    <mu1>0.9</mu1>
    <mu2>0.9</mu2>
  </gazebo>
  <link name="RLEG_LINK3">
    <visual>
      <origin rpy="0 -0 0" xyz="0 0 -0.3"/>
      <geometry>
        <mesh filename="package://hrpsys_ros_bridge_tutorials/models/HRP2JSKNTS_meshes/RLEG_LINK3_mesh.dae" scale="1 1 1"/>
      </geometry>
    </visual>
    <collision>
      <origin rpy="0 -0 0" xyz="0 0 -0.3"/>
      <geometry>
        <mesh filename="package://hrpsys_ros_bridge_tutorials/models/HRP2JSKNTS_meshes/RLEG_LINK3_mesh.dae" scale="1 1 1"/>
      </geometry>
    </collision>
    <inertial>
      <mass value="1.74762"/>
      <origin rpy="0 -0 0" xyz="0.0179878 -0.0579164 -0.13839"/>
      <inertia ixx="0.0223269" ixy="-9.39152e-05" ixz="-0.00224766" iyy="0.022506" iyz="-0.000745178" izz="0.0045544"/>
    </inertial>
  </link>
  <gazebo reference="RLEG_LINK3">
    <mu1>0.9</mu1>
    <mu2>0.9</mu2>
  </gazebo>
  <link name="RLEG_LINK4">
    <visual>
      <origin rpy="0 -0 0" xyz="0 -0.035 -0.3"/>
      <geometry>
        <mesh filename="package://hrpsys_ros_bridge_tutorials/models/HRP2JSKNTS_meshes/RLEG_LINK4_mesh.dae" scale="1 1 1"/>
      </geometry>
    </visual>
    <collision>
      <origin rpy="0 -0 0" xyz="0 -0.035 -0.3"/>
      <geometry>
        <mesh filename="package://hrpsys_ros_bridge_tutorials/models/HRP2JSKNTS_meshes/RLEG_LINK4_mesh.dae" scale="1 1 1"/>
      </geometry>
    </collision>
    <inertial>
      <mass value="0.65375"/>
      <origin rpy="0 -0 0" xyz="0.00827083 -0.00133301 -0.002418"/>
      <inertia ixx="0.00027773" ixy="-5.26e-06" ixz="1.354e-05" iyy="0.00078966" iyz="-3.59e-06" izz="0.00086039"/>
    </inertial>
  </link>
  <gazebo reference="RLEG_LINK4">
    <mu1>0.9</mu1>
    <mu2>0.9</mu2>
  </gazebo>
  <link name="RLEG_LINK5">
    <visual>
      <origin rpy="0 -0 0" xyz="0 0 0"/>
      <geometry>
        <mesh filename="package://hrpsys_ros_bridge_tutorials/models/HRP2JSKNTS_meshes/RLEG_LINK5_mesh.dae" scale="1 1 1"/>
      </geometry>
    </visual>
    <collision>
      <origin rpy="0 -0 0" xyz="0 0 0"/>
      <geometry>
        <mesh filename="package://hrpsys_ros_bridge_tutorials/models/HRP2JSKNTS_meshes/RLEG_LINK5_mesh.dae" scale="1 1 1"/>
      </geometry>
    </collision>
    <inertial>
      <mass value="1.63877"/>
      <origin rpy="0 -0 0" xyz="-0.00066419 -0.00468922 -0.0653813"/>
      <inertia ixx="0.00400076" ixy="9.983e-05" ixz="0.00079295" iyy="0.00687611" iyz="-0.00018541" izz="0.00711516"/>
    </inertial>
  </link>
  <gazebo reference="RLEG_LINK5">
    <mu1>0.9</mu1>
    <mu2>0.9</mu2>
  </gazebo>
  <link name="RLEG_LINK6">
    <visual>
      <origin rpy="0 -0 0" xyz="0.115 0 -0.074"/>
      <geometry>
        <mesh filename="package://hrpsys_ros_bridge_tutorials/models/HRP2JSKNTS_meshes/RLEG_LINK6_mesh.dae" scale="1 1 1"/>
      </geometry>
    </visual>
    <collision>
      <origin rpy="0 -0 0" xyz="0.115 0 -0.074"/>
      <geometry>
        <mesh filename="package://hrpsys_ros_bridge_tutorials/models/HRP2JSKNTS_meshes/RLEG_LINK6_mesh.dae" scale="1 1 1"/>
      </geometry>
    </collision>
    <inertial>
      <mass value="0.509152"/>
      <origin rpy="0 -0 0" xyz="0.0199389 -0.0138546 -0.0104375"/>
      <inertia ixx="0.00076266" ixy="2.741e-05" ixz="2.69e-06" iyy="0.00035733" iyz="1.182e-05" izz="0.00095164"/>
    </inertial>
  </link>
  <gazebo reference="RLEG_LINK6">
    <mu1>0.9</mu1>
    <mu2>0.9</mu2>
  </gazebo>
  <joint name="CHEST_JOINT0" type="revolute">
    <parent link="BODY"/>
    <child link="CHEST_LINK0"/>
    <origin rpy="0 -0 0 " xyz="0.032 0 0.3507"/>
    <axis xyz="0 0 1"/>
    <limit effort="151.8" lower="-0.785398" upper="0.785398" velocity="4.40217"/>
    <dynamics damping="0.2" friction="0"/>
  </joint>
  <transmission name="CHEST_JOINT0_trans" type="pr2_mechanism_model/SimpleTransmission">
    <actuator name="CHEST_JOINT0_motor"/>
    <joint name="CHEST_JOINT0"/>
    <mechanicalReduction>1</mechanicalReduction>
  </transmission>
  <gazebo reference="CHEST_JOINT0">
    <cfmDamping>0.4</cfmDamping>
  </gazebo>
  <joint name="CHEST_JOINT1" type="revolute">
    <parent link="CHEST_LINK0"/>
    <child link="CHEST_LINK1"/>
    <origin rpy="0 -0 0 " xyz="0 0 0"/>
    <axis xyz="0 1 0"/>
    <limit effort="278.9" lower="-0.0872665" upper="1.0472" velocity="2.3963"/>
    <dynamics damping="0.2" friction="0"/>
  </joint>
  <transmission name="CHEST_JOINT1_trans" type="pr2_mechanism_model/SimpleTransmission">
    <actuator name="CHEST_JOINT1_motor"/>
    <joint name="CHEST_JOINT1"/>
    <mechanicalReduction>1</mechanicalReduction>
  </transmission>
  <gazebo reference="CHEST_JOINT1">
    <cfmDamping>0.4</cfmDamping>
  </gazebo>
  <joint name="HEAD_JOINT0" type="revolute">
    <parent link="CHEST_LINK1"/>
    <child link="HEAD_LINK0"/>
    <origin rpy="0 -0 0 " xyz="-0.007 0 0.2973"/>
    <axis xyz="0 0 1"/>
    <limit effort="9.6" lower="-0.785398" upper="0.785398" velocity="6.87679"/>
    <dynamics damping="0.2" friction="0"/>
  </joint>
  <transmission name="HEAD_JOINT0_trans" type="pr2_mechanism_model/SimpleTransmission">
    <actuator name="HEAD_JOINT0_motor"/>
    <joint name="HEAD_JOINT0"/>
    <mechanicalReduction>1</mechanicalReduction>
  </transmission>
  <gazebo reference="HEAD_JOINT0">
    <cfmDamping>0.4</cfmDamping>
  </gazebo>
  <joint name="HEAD_JOINT1" type="revolute">
    <parent link="HEAD_LINK0"/>
    <child link="HEAD_LINK1"/>
    <origin rpy="0 -0 0 " xyz="0 0 0"/>
    <axis xyz="0 1 0"/>
    <limit effort="9.6" lower="-0.523599" upper="0.759218" velocity="6.87679"/>
    <dynamics damping="0.2" friction="0"/>
  </joint>
  <transmission name="HEAD_JOINT1_trans" type="pr2_mechanism_model/SimpleTransmission">
    <actuator name="HEAD_JOINT1_motor"/>
    <joint name="HEAD_JOINT1"/>
    <mechanicalReduction>1</mechanicalReduction>
  </transmission>
  <gazebo reference="HEAD_JOINT1">
    <cfmDamping>0.4</cfmDamping>
  </gazebo>
  <joint name="LARM_JOINT0" type="revolute">
    <parent link="CHEST_LINK1"/>
    <child link="LARM_LINK0"/>
    <origin rpy="0 -0 0 " xyz="0.008 0.28 0.181"/>
    <axis xyz="0 1 0"/>
    <limit effort="160.3" lower="-3.14159" upper="1.0472" velocity="4.17044"/>
    <dynamics damping="0.2" friction="0"/>
  </joint>
  <transmission name="LARM_JOINT0_trans" type="pr2_mechanism_model/SimpleTransmission">
    <actuator name="LARM_JOINT0_motor"/>
    <joint name="LARM_JOINT0"/>
    <mechanicalReduction>1</mechanicalReduction>
  </transmission>
  <gazebo reference="LARM_JOINT0">
    <cfmDamping>0.4</cfmDamping>
  </gazebo>
  <joint name="LARM_JOINT1" type="revolute">
    <parent link="LARM_LINK0"/>
    <child link="LARM_LINK1"/>
    <origin rpy="0 -0 0 " xyz="0 0 0"/>
    <axis xyz="1 0 0"/>
    <limit effort="100.4" lower="-0.174533" upper="1.65806" velocity="2.4192"/>
    <dynamics damping="0.2" friction="0"/>
  </joint>
  <transmission name="LARM_JOINT1_trans" type="pr2_mechanism_model/SimpleTransmission">
    <actuator name="LARM_JOINT1_motor"/>
    <joint name="LARM_JOINT1"/>
    <mechanicalReduction>1</mechanicalReduction>
  </transmission>
  <gazebo reference="LARM_JOINT1">
    <cfmDamping>0.4</cfmDamping>
  </gazebo>
  <joint name="LARM_JOINT2" type="revolute">
    <parent link="LARM_LINK1"/>
    <child link="LARM_LINK2"/>
    <origin rpy="0 -0 0 " xyz="0 0 0"/>
    <axis xyz="0 0 1"/>
    <limit effort="48.7" lower="-1.6057" upper="1.6057" velocity="4.15699"/>
    <dynamics damping="0.2" friction="0"/>
  </joint>
  <transmission name="LARM_JOINT2_trans" type="pr2_mechanism_model/SimpleTransmission">
    <actuator name="LARM_JOINT2_motor"/>
    <joint name="LARM_JOINT2"/>
    <mechanicalReduction>1</mechanicalReduction>
  </transmission>
  <gazebo reference="LARM_JOINT2">
    <cfmDamping>0.4</cfmDamping>
  </gazebo>
  <joint name="LARM_JOINT3" type="revolute">
    <parent link="LARM_LINK2"/>
    <child link="LARM_LINK3"/>
    <origin rpy="0 -0 0 " xyz="0 0 -0.25"/>
    <axis xyz="0 1 0"/>
    <limit effort="108.5" lower="-2.3911" upper="0.0349066" velocity="2.23776"/>
    <dynamics damping="0.2" friction="0"/>
  </joint>
  <transmission name="LARM_JOINT3_trans" type="pr2_mechanism_model/SimpleTransmission">
    <actuator name="LARM_JOINT3_motor"/>
    <joint name="LARM_JOINT3"/>
    <mechanicalReduction>1</mechanicalReduction>
  </transmission>
  <gazebo reference="LARM_JOINT3">
    <cfmDamping>0.4</cfmDamping>
  </gazebo>
  <joint name="LARM_JOINT4" type="revolute">
    <parent link="LARM_LINK3"/>
    <child link="LARM_LINK4"/>
    <origin rpy="0 -0 0 " xyz="0 0 -0.25"/>
    <axis xyz="0 0 1"/>
    <limit effort="13.9" lower="-1.85005" upper="1.85005" velocity="4.72794"/>
    <dynamics damping="0.2" friction="0"/>
  </joint>
  <transmission name="LARM_JOINT4_trans" type="pr2_mechanism_model/SimpleTransmission">
    <actuator name="LARM_JOINT4_motor"/>
    <joint name="LARM_JOINT4"/>
    <mechanicalReduction>1</mechanicalReduction>
  </transmission>
  <gazebo reference="LARM_JOINT4">
    <cfmDamping>0.4</cfmDamping>
  </gazebo>
  <joint name="LARM_JOINT5" type="revolute">
    <parent link="LARM_LINK4"/>
    <child link="LARM_LINK5"/>
    <origin rpy="0 -0 0 " xyz="0 0 0"/>
    <axis xyz="1 0 0"/>
    <limit effort="18.74" lower="-1.6057" upper="1.6057" velocity="6.63609"/>
    <dynamics damping="0.2" friction="0"/>
  </joint>
  <transmission name="LARM_JOINT5_trans" type="pr2_mechanism_model/SimpleTransmission">
    <actuator name="LARM_JOINT5_motor"/>
    <joint name="LARM_JOINT5"/>
    <mechanicalReduction>1</mechanicalReduction>
  </transmission>
  <gazebo reference="LARM_JOINT5">
    <cfmDamping>0.4</cfmDamping>
  </gazebo>
  <joint name="LARM_JOINT6" type="revolute">
    <parent link="LARM_LINK5"/>
    <child link="LARM_LINK6"/>
    <origin rpy="0 -0 0 " xyz="0 0 0"/>
    <axis xyz="0 1 0"/>
    <limit effort="16.02" lower="-1.6057" upper="1.6057" velocity="2.77088"/>
    <dynamics damping="0.2" friction="0"/>
  </joint>
  <transmission name="LARM_JOINT6_trans" type="pr2_mechanism_model/SimpleTransmission">
    <actuator name="LARM_JOINT6_motor"/>
    <joint name="LARM_JOINT6"/>
    <mechanicalReduction>1</mechanicalReduction>
  </transmission>
  <gazebo reference="LARM_JOINT6">
    <cfmDamping>0.4</cfmDamping>
  </gazebo>
  <joint name="LARM_JOINT7" type="revolute">
    <parent link="LARM_LINK6"/>
    <child link="LARM_LINK7"/>
    <origin rpy="0 -0 0 " xyz="0 -0.0169 -0.114"/>
    <axis xyz="1 0 0"/>
    <limit effort="13.9" lower="-2.35619" upper="0.279253" velocity="4.72794"/>
    <dynamics damping="0.2" friction="0"/>
  </joint>
  <transmission name="LARM_JOINT7_trans" type="pr2_mechanism_model/SimpleTransmission">
    <actuator name="LARM_JOINT7_motor"/>
    <joint name="LARM_JOINT7"/>
    <mechanicalReduction>1</mechanicalReduction>
  </transmission>
  <gazebo reference="LARM_JOINT7">
    <cfmDamping>0.4</cfmDamping>
  </gazebo>
  <joint name="RARM_JOINT0" type="revolute">
    <parent link="CHEST_LINK1"/>
    <child link="RARM_LINK0"/>
    <origin rpy="0 -0 0 " xyz="0.008 -0.28 0.181"/>
    <axis xyz="0 1 0"/>
    <limit effort="160.3" lower="-3.14159" upper="1.0472" velocity="4.17044"/>
    <dynamics damping="0.2" friction="0"/>
  </joint>
  <transmission name="RARM_JOINT0_trans" type="pr2_mechanism_model/SimpleTransmission">
    <actuator name="RARM_JOINT0_motor"/>
    <joint name="RARM_JOINT0"/>
    <mechanicalReduction>1</mechanicalReduction>
  </transmission>
  <gazebo reference="RARM_JOINT0">
    <cfmDamping>0.4</cfmDamping>
  </gazebo>
  <joint name="RARM_JOINT1" type="revolute">
    <parent link="RARM_LINK0"/>
    <child link="RARM_LINK1"/>
    <origin rpy="0 -0 0 " xyz="0 0 0"/>
    <axis xyz="1 0 0"/>
    <limit effort="100.4" lower="-1.65806" upper="0.174533" velocity="2.4192"/>
    <dynamics damping="0.2" friction="0"/>
  </joint>
  <transmission name="RARM_JOINT1_trans" type="pr2_mechanism_model/SimpleTransmission">
    <actuator name="RARM_JOINT1_motor"/>
    <joint name="RARM_JOINT1"/>
    <mechanicalReduction>1</mechanicalReduction>
  </transmission>
  <gazebo reference="RARM_JOINT1">
    <cfmDamping>0.4</cfmDamping>
  </gazebo>
  <joint name="RARM_JOINT2" type="revolute">
    <parent link="RARM_LINK1"/>
    <child link="RARM_LINK2"/>
    <origin rpy="0 -0 0 " xyz="0 0 0"/>
    <axis xyz="0 0 1"/>
    <limit effort="48.7" lower="-1.6057" upper="1.6057" velocity="4.15699"/>
    <dynamics damping="0.2" friction="0"/>
  </joint>
  <transmission name="RARM_JOINT2_trans" type="pr2_mechanism_model/SimpleTransmission">
    <actuator name="RARM_JOINT2_motor"/>
    <joint name="RARM_JOINT2"/>
    <mechanicalReduction>1</mechanicalReduction>
  </transmission>
  <gazebo reference="RARM_JOINT2">
    <cfmDamping>0.4</cfmDamping>
  </gazebo>
  <joint name="RARM_JOINT3" type="revolute">
    <parent link="RARM_LINK2"/>
    <child link="RARM_LINK3"/>
    <origin rpy="0 -0 0 " xyz="0 0 -0.25"/>
    <axis xyz="0 1 0"/>
    <limit effort="108.5" lower="-2.3911" upper="0.0349066" velocity="2.23776"/>
    <dynamics damping="0.2" friction="0"/>
  </joint>
  <transmission name="RARM_JOINT3_trans" type="pr2_mechanism_model/SimpleTransmission">
    <actuator name="RARM_JOINT3_motor"/>
    <joint name="RARM_JOINT3"/>
    <mechanicalReduction>1</mechanicalReduction>
  </transmission>
  <gazebo reference="RARM_JOINT3">
    <cfmDamping>0.4</cfmDamping>
  </gazebo>
  <joint name="RARM_JOINT4" type="revolute">
    <parent link="RARM_LINK3"/>
    <child link="RARM_LINK4"/>
    <origin rpy="0 -0 0 " xyz="0 0 -0.25"/>
    <axis xyz="0 0 1"/>
    <limit effort="13.9" lower="-1.85005" upper="1.85005" velocity="4.72794"/>
    <dynamics damping="0.2" friction="0"/>
  </joint>
  <transmission name="RARM_JOINT4_trans" type="pr2_mechanism_model/SimpleTransmission">
    <actuator name="RARM_JOINT4_motor"/>
    <joint name="RARM_JOINT4"/>
    <mechanicalReduction>1</mechanicalReduction>
  </transmission>
  <gazebo reference="RARM_JOINT4">
    <cfmDamping>0.4</cfmDamping>
  </gazebo>
  <joint name="RARM_JOINT5" type="revolute">
    <parent link="RARM_LINK4"/>
    <child link="RARM_LINK5"/>
    <origin rpy="0 -0 0 " xyz="0 0 0"/>
    <axis xyz="1 0 0"/>
    <limit effort="18.74" lower="-1.6057" upper="1.6057" velocity="6.63609"/>
    <dynamics damping="0.2" friction="0"/>
  </joint>
  <transmission name="RARM_JOINT5_trans" type="pr2_mechanism_model/SimpleTransmission">
    <actuator name="RARM_JOINT5_motor"/>
    <joint name="RARM_JOINT5"/>
    <mechanicalReduction>1</mechanicalReduction>
  </transmission>
  <gazebo reference="RARM_JOINT5">
    <cfmDamping>0.4</cfmDamping>
  </gazebo>
  <joint name="RARM_JOINT6" type="revolute">
    <parent link="RARM_LINK5"/>
    <child link="RARM_LINK6"/>
    <origin rpy="0 -0 0 " xyz="0 0 0"/>
    <axis xyz="0 1 0"/>
    <limit effort="16.02" lower="-1.6057" upper="1.6057" velocity="2.77088"/>
    <dynamics damping="0.2" friction="0"/>
  </joint>
  <transmission name="RARM_JOINT6_trans" type="pr2_mechanism_model/SimpleTransmission">
    <actuator name="RARM_JOINT6_motor"/>
    <joint name="RARM_JOINT6"/>
    <mechanicalReduction>1</mechanicalReduction>
  </transmission>
  <gazebo reference="RARM_JOINT6">
    <cfmDamping>0.4</cfmDamping>
  </gazebo>
  <joint name="RARM_JOINT7" type="revolute">
    <parent link="RARM_LINK6"/>
    <child link="RARM_LINK7"/>
    <origin rpy="0 -0 0 " xyz="0 0.0169 -0.114"/>
    <axis xyz="1 0 0"/>
    <limit effort="13.9" lower="-0.279253" upper="2.35619" velocity="4.72794"/>
    <dynamics damping="0.2" friction="0"/>
  </joint>
  <transmission name="RARM_JOINT7_trans" type="pr2_mechanism_model/SimpleTransmission">
    <actuator name="RARM_JOINT7_motor"/>
    <joint name="RARM_JOINT7"/>
    <mechanicalReduction>1</mechanicalReduction>
  </transmission>
  <gazebo reference="RARM_JOINT7">
    <cfmDamping>0.4</cfmDamping>
  </gazebo>
  <joint name="LLEG_JOINT0" type="revolute">
    <parent link="BODY"/>
    <child link="LLEG_LINK0"/>
    <origin rpy="0 -0 0 " xyz="0 0.06 0"/>
    <axis xyz="0 0 1"/>
    <limit effort="86.2" lower="-0.523599" upper="0.785398" velocity="3.54108"/>
    <dynamics damping="0.2" friction="0"/>
  </joint>
  <transmission name="LLEG_JOINT0_trans" type="pr2_mechanism_model/SimpleTransmission">
    <actuator name="LLEG_JOINT0_motor"/>
    <joint name="LLEG_JOINT0"/>
    <mechanicalReduction>1</mechanicalReduction>
  </transmission>
  <gazebo reference="LLEG_JOINT0">
    <cfmDamping>0.4</cfmDamping>
  </gazebo>
  <joint name="LLEG_JOINT1" type="revolute">
    <parent link="LLEG_LINK0"/>
    <child link="LLEG_LINK1"/>
    <origin rpy="0 -0 0 " xyz="0 0 0"/>
    <axis xyz="1 0 0"/>
    <limit effort="175.4" lower="-0.349066" upper="0.610865" velocity="3.80952"/>
    <dynamics damping="0.2" friction="0"/>
  </joint>
  <transmission name="LLEG_JOINT1_trans" type="pr2_mechanism_model/SimpleTransmission">
    <actuator name="LLEG_JOINT1_motor"/>
    <joint name="LLEG_JOINT1"/>
    <mechanicalReduction>1</mechanicalReduction>
  </transmission>
  <gazebo reference="LLEG_JOINT1">
    <cfmDamping>0.4</cfmDamping>
  </gazebo>
  <joint name="LLEG_JOINT2" type="revolute">
    <parent link="LLEG_LINK1"/>
    <child link="LLEG_LINK2"/>
    <origin rpy="0 -0 0 " xyz="0 0 0"/>
    <axis xyz="0 1 0"/>
    <limit effort="151.4" lower="-2.18166" upper="0.733038" velocity="4.42233"/>
    <dynamics damping="0.2" friction="0"/>
  </joint>
  <transmission name="LLEG_JOINT2_trans" type="pr2_mechanism_model/SimpleTransmission">
    <actuator name="LLEG_JOINT2_motor"/>
    <joint name="LLEG_JOINT2"/>
    <mechanicalReduction>1</mechanicalReduction>
  </transmission>
  <gazebo reference="LLEG_JOINT2">
    <cfmDamping>0.4</cfmDamping>
  </gazebo>
  <joint name="LLEG_JOINT3" type="revolute">
    <parent link="LLEG_LINK2"/>
    <child link="LLEG_LINK3"/>
    <origin rpy="0 -0 0 " xyz="0 0 -0.3"/>
    <axis xyz="0 1 0"/>
    <limit effort="168.3" lower="-0.0349066" upper="2.61799" velocity="3.9801"/>
    <dynamics damping="0.2" friction="0"/>
  </joint>
  <transmission name="LLEG_JOINT3_trans" type="pr2_mechanism_model/SimpleTransmission">
    <actuator name="LLEG_JOINT3_motor"/>
    <joint name="LLEG_JOINT3"/>
    <mechanicalReduction>1</mechanicalReduction>
  </transmission>
  <gazebo reference="LLEG_JOINT3">
    <cfmDamping>0.4</cfmDamping>
  </gazebo>
  <joint name="LLEG_JOINT4" type="revolute">
    <parent link="LLEG_LINK3"/>
    <child link="LLEG_LINK4"/>
    <origin rpy="0 -0 0 " xyz="0 0.035 -0.3"/>
    <axis xyz="0 1 0"/>
    <limit effort="131.6" lower="-1.22173" upper="0.733038" velocity="5.07937"/>
    <dynamics damping="0.2" friction="0"/>
  </joint>
  <transmission name="LLEG_JOINT4_trans" type="pr2_mechanism_model/SimpleTransmission">
    <actuator name="LLEG_JOINT4_motor"/>
    <joint name="LLEG_JOINT4"/>
    <mechanicalReduction>1</mechanicalReduction>
  </transmission>
  <gazebo reference="LLEG_JOINT4">
    <cfmDamping>0.4</cfmDamping>
  </gazebo>
  <joint name="LLEG_JOINT5" type="revolute">
    <parent link="LLEG_LINK4"/>
    <child link="LLEG_LINK5"/>
    <origin rpy="0 -0 0 " xyz="0 0 0"/>
    <axis xyz="1 0 0"/>
    <limit effort="73.1" lower="-0.610865" upper="0.349066" velocity="9.14286"/>
    <dynamics damping="0.2" friction="0"/>
  </joint>
  <transmission name="LLEG_JOINT5_trans" type="pr2_mechanism_model/SimpleTransmission">
    <actuator name="LLEG_JOINT5_motor"/>
    <joint name="LLEG_JOINT5"/>
    <mechanicalReduction>1</mechanicalReduction>
  </transmission>
  <gazebo reference="LLEG_JOINT5">
    <cfmDamping>0.4</cfmDamping>
  </gazebo>
  <joint name="LLEG_JOINT6" type="revolute">
    <parent link="LLEG_LINK5"/>
    <child link="LLEG_LINK6"/>
    <origin rpy="0 -0 0 " xyz="0.115 0 -0.074"/>
    <axis xyz="0 1 0"/>
    <limit effort="35.88" lower="-1.0472" upper="0.279253" velocity="8.85929"/>
    <dynamics damping="0.2" friction="0"/>
  </joint>
  <transmission name="LLEG_JOINT6_trans" type="pr2_mechanism_model/SimpleTransmission">
    <actuator name="LLEG_JOINT6_motor"/>
    <joint name="LLEG_JOINT6"/>
    <mechanicalReduction>1</mechanicalReduction>
  </transmission>
  <gazebo reference="LLEG_JOINT6">
    <cfmDamping>0.4</cfmDamping>
  </gazebo>
  <joint name="RLEG_JOINT0" type="revolute">
    <parent link="BODY"/>
    <child link="RLEG_LINK0"/>
    <origin rpy="0 -0 0 " xyz="0 -0.06 0"/>
    <axis xyz="0 0 1"/>
    <limit effort="86.2" lower="-0.785398" upper="0.523599" velocity="3.54108"/>
    <dynamics damping="0.2" friction="0"/>
  </joint>
  <transmission name="RLEG_JOINT0_trans" type="pr2_mechanism_model/SimpleTransmission">
    <actuator name="RLEG_JOINT0_motor"/>
    <joint name="RLEG_JOINT0"/>
    <mechanicalReduction>1</mechanicalReduction>
  </transmission>
  <gazebo reference="RLEG_JOINT0">
    <cfmDamping>0.4</cfmDamping>
  </gazebo>
  <joint name="RLEG_JOINT1" type="revolute">
    <parent link="RLEG_LINK0"/>
    <child link="RLEG_LINK1"/>
    <origin rpy="0 -0 0 " xyz="0 0 0"/>
    <axis xyz="1 0 0"/>
    <limit effort="175.4" lower="-0.610865" upper="0.349066" velocity="3.80952"/>
    <dynamics damping="0.2" friction="0"/>
  </joint>
  <transmission name="RLEG_JOINT1_trans" type="pr2_mechanism_model/SimpleTransmission">
    <actuator name="RLEG_JOINT1_motor"/>
    <joint name="RLEG_JOINT1"/>
    <mechanicalReduction>1</mechanicalReduction>
  </transmission>
  <gazebo reference="RLEG_JOINT1">
    <cfmDamping>0.4</cfmDamping>
  </gazebo>
  <joint name="RLEG_JOINT2" type="revolute">
    <parent link="RLEG_LINK1"/>
    <child link="RLEG_LINK2"/>
    <origin rpy="0 -0 0 " xyz="0 0 0"/>
    <axis xyz="0 1 0"/>
    <limit effort="151.4" lower="-2.18166" upper="0.733038" velocity="4.42233"/>
    <dynamics damping="0.2" friction="0"/>
  </joint>
  <transmission name="RLEG_JOINT2_trans" type="pr2_mechanism_model/SimpleTransmission">
    <actuator name="RLEG_JOINT2_motor"/>
    <joint name="RLEG_JOINT2"/>
    <mechanicalReduction>1</mechanicalReduction>
  </transmission>
  <gazebo reference="RLEG_JOINT2">
    <cfmDamping>0.4</cfmDamping>
  </gazebo>
  <joint name="RLEG_JOINT3" type="revolute">
    <parent link="RLEG_LINK2"/>
    <child link="RLEG_LINK3"/>
    <origin rpy="0 -0 0 " xyz="0 0 -0.3"/>
    <axis xyz="0 1 0"/>
    <limit effort="168.3" lower="-0.0349066" upper="2.61799" velocity="3.9801"/>
    <dynamics damping="0.2" friction="0"/>
  </joint>
  <transmission name="RLEG_JOINT3_trans" type="pr2_mechanism_model/SimpleTransmission">
    <actuator name="RLEG_JOINT3_motor"/>
    <joint name="RLEG_JOINT3"/>
    <mechanicalReduction>1</mechanicalReduction>
  </transmission>
  <gazebo reference="RLEG_JOINT3">
    <cfmDamping>0.4</cfmDamping>
  </gazebo>
  <joint name="RLEG_JOINT4" type="revolute">
    <parent link="RLEG_LINK3"/>
    <child link="RLEG_LINK4"/>
    <origin rpy="0 -0 0 " xyz="0 -0.035 -0.3"/>
    <axis xyz="0 1 0"/>
    <limit effort="131.6" lower="-1.22173" upper="0.733038" velocity="5.07937"/>
    <dynamics damping="0.2" friction="0"/>
  </joint>
  <transmission name="RLEG_JOINT4_trans" type="pr2_mechanism_model/SimpleTransmission">
    <actuator name="RLEG_JOINT4_motor"/>
    <joint name="RLEG_JOINT4"/>
    <mechanicalReduction>1</mechanicalReduction>
  </transmission>
  <gazebo reference="RLEG_JOINT4">
    <cfmDamping>0.4</cfmDamping>
  </gazebo>
  <joint name="RLEG_JOINT5" type="revolute">
    <parent link="RLEG_LINK4"/>
    <child link="RLEG_LINK5"/>
    <origin rpy="0 -0 0 " xyz="0 0 0"/>
    <axis xyz="1 0 0"/>
    <limit effort="73.1" lower="-0.349066" upper="0.610865" velocity="9.14286"/>
    <dynamics damping="0.2" friction="0"/>
  </joint>
  <transmission name="RLEG_JOINT5_trans" type="pr2_mechanism_model/SimpleTransmission">
    <actuator name="RLEG_JOINT5_motor"/>
    <joint name="RLEG_JOINT5"/>
    <mechanicalReduction>1</mechanicalReduction>
  </transmission>
  <gazebo reference="RLEG_JOINT5">
    <cfmDamping>0.4</cfmDamping>
  </gazebo>
  <joint name="RLEG_JOINT6" type="revolute">
    <parent link="RLEG_LINK5"/>
    <child link="RLEG_LINK6"/>
    <origin rpy="0 -0 0 " xyz="0.115 0 -0.074"/>
    <axis xyz="0 1 0"/>
    <limit effort="35.88" lower="-1.0472" upper="0.279253" velocity="8.85929"/>
    <dynamics damping="0.2" friction="0"/>
  </joint>
  <transmission name="RLEG_JOINT6_trans" type="pr2_mechanism_model/SimpleTransmission">
    <actuator name="RLEG_JOINT6_motor"/>
    <joint name="RLEG_JOINT6"/>
    <mechanicalReduction>1</mechanicalReduction>
  </transmission>
  <gazebo reference="RLEG_JOINT6">
    <cfmDamping>0.4</cfmDamping>
  </gazebo>
  <link name="LARM_LINK6">
    <visual>
      <origin rpy="0 -0 0" xyz="0 0 0"/>
      <geometry>
        <mesh filename="package://hrpsys_ros_bridge_tutorials/models/HRP3HAND_L_meshes/LARM_LINK6_mesh.dae" scale="1 1 1"/>
      </geometry>
    </visual>
    <collision>
      <origin rpy="0 -0 0" xyz="0 0 0"/>
      <geometry>
        <mesh filename="package://hrpsys_ros_bridge_tutorials/models/HRP3HAND_L_meshes/LARM_LINK6_mesh.dae" scale="1 1 1"/>
      </geometry>
    </collision>
    <inertial>
      <mass value="1.33256"/>
      <origin rpy="0 -0 0" xyz="0.00067085 0.00738842 -0.085722"/>
      <inertia ixx="0.00227076" ixy="6.3e-07" ixz="3.217e-05" iyy="0.00214173" iyz="-3.72e-06" izz="0.00067255"/>
    </inertial>
  </link>
  <gazebo reference="LARM_LINK6">
    <mu1>0.9</mu1>
    <mu2>0.9</mu2>
  </gazebo>
  <link name="L_INDEXMP_R_LINK">
    <visual>
      <origin rpy="0 -0 0" xyz="0 -0.0102 -0.1547"/>
      <geometry>
        <mesh filename="package://hrpsys_ros_bridge_tutorials/models/HRP3HAND_L_meshes/L_INDEXMP_R_LINK_mesh.dae" scale="1 1 1"/>
      </geometry>
    </visual>
    <collision>
      <origin rpy="0 -0 0" xyz="0 -0.0102 -0.1547"/>
      <geometry>
        <mesh filename="package://hrpsys_ros_bridge_tutorials/models/HRP3HAND_L_meshes/L_INDEXMP_R_LINK_mesh.dae" scale="1 1 1"/>
      </geometry>
    </collision>
    <inertial>
      <mass value="0.0158629"/>
      <origin rpy="0 -0 0" xyz="0.00509194 0.00581104 6.273e-05"/>
      <inertia ixx="9.9e-07" ixy="-7.6e-07" ixz="-7.94093e-23" iyy="1.61e-06" iyz="-1e-08" izz="2.16e-06"/>
    </inertial>
  </link>
  <gazebo reference="L_INDEXMP_R_LINK">
    <mu1>0.9</mu1>
    <mu2>0.9</mu2>
  </gazebo>
  <link name="L_INDEXMP_P_LINK">
    <visual>
      <origin rpy="0 -0 0" xyz="0.02 0 0"/>
      <geometry>
        <mesh filename="package://hrpsys_ros_bridge_tutorials/models/HRP3HAND_L_meshes/L_INDEXMP_P_LINK_mesh.dae" scale="1 1 1"/>
      </geometry>
    </visual>
    <collision>
      <origin rpy="0 -0 0" xyz="0.02 0 0"/>
      <geometry>
        <mesh filename="package://hrpsys_ros_bridge_tutorials/models/HRP3HAND_L_meshes/L_INDEXMP_P_LINK_mesh.dae" scale="1 1 1"/>
      </geometry>
    </collision>
    <inertial>
      <mass value="0.106231"/>
      <origin rpy="0 -0 0" xyz="-0.00078463 -0.00129762 -0.0281757"/>
      <inertia ixx="5.089e-05" ixy="-6.2e-07" ixz="-1.87e-06" iyy="4.739e-05" iyz="-1.05e-05" izz="1.005e-05"/>
    </inertial>
  </link>
  <gazebo reference="L_INDEXMP_P_LINK">
    <mu1>0.9</mu1>
    <mu2>0.9</mu2>
  </gazebo>
  <link name="L_INDEXPIP_R_LINK">
    <visual>
      <origin rpy="0 -0 0" xyz="0 -0.01125 -0.055"/>
      <geometry>
        <mesh filename="package://hrpsys_ros_bridge_tutorials/models/HRP3HAND_L_meshes/L_INDEXPIP_R_LINK_mesh.dae" scale="1 1 1"/>
      </geometry>
    </visual>
    <collision>
      <origin rpy="0 -0 0" xyz="0 -0.01125 -0.055"/>
      <geometry>
        <mesh filename="package://hrpsys_ros_bridge_tutorials/models/HRP3HAND_L_meshes/L_INDEXPIP_R_LINK_mesh.dae" scale="1 1 1"/>
      </geometry>
    </collision>
    <inertial>
      <mass value="0.0215832"/>
      <origin rpy="0 -0 0" xyz="0.0210676 -0.0134797 -0.0204042"/>
      <inertia ixx="4.06e-06" ixy="-2.2e-07" ixz="-2.9e-07" iyy="2.34e-06" iyz="-1.55e-06" izz="3.05e-06"/>
    </inertial>
  </link>
  <gazebo reference="L_INDEXPIP_R_LINK">
    <mu1>0.9</mu1>
    <mu2>0.9</mu2>
  </gazebo>
  <link name="L_MIDDLEPIP_R_LINK">
    <visual>
      <origin rpy="0 -0 0" xyz="0 -0.02145 -0.2097"/>
      <geometry>
        <mesh filename="package://hrpsys_ros_bridge_tutorials/models/HRP3HAND_L_meshes/L_MIDDLEPIP_R_LINK_mesh.dae" scale="1 1 1"/>
      </geometry>
    </visual>
    <collision>
      <origin rpy="0 -0 0" xyz="0 -0.02145 -0.2097"/>
      <geometry>
        <mesh filename="package://hrpsys_ros_bridge_tutorials/models/HRP3HAND_L_meshes/L_MIDDLEPIP_R_LINK_mesh.dae" scale="1 1 1"/>
      </geometry>
    </collision>
    <inertial>
      <mass value="0.0367086"/>
      <origin rpy="0 -0 0" xyz="-0.0171953 -0.0140037 -0.0195553"/>
      <inertia ixx="9.9e-06" ixy="-6.2e-07" ixz="-8.7e-07" iyy="1.003e-05" iyz="-3.95e-06" izz="1.043e-05"/>
    </inertial>
  </link>
  <gazebo reference="L_MIDDLEPIP_R_LINK">
    <mu1>0.9</mu1>
    <mu2>0.9</mu2>
  </gazebo>
  <link name="L_THUMBCM_Y_LINK">
    <visual>
      <origin rpy="0 -0 0" xyz="0 -0.0102 -0.1292"/>
      <geometry>
        <mesh filename="package://hrpsys_ros_bridge_tutorials/models/HRP3HAND_L_meshes/L_THUMBCM_Y_LINK_mesh.dae" scale="1 1 1"/>
      </geometry>
    </visual>
    <collision>
      <origin rpy="0 -0 0" xyz="0 -0.0102 -0.1292"/>
      <geometry>
        <mesh filename="package://hrpsys_ros_bridge_tutorials/models/HRP3HAND_L_meshes/L_THUMBCM_Y_LINK_mesh.dae" scale="1 1 1"/>
      </geometry>
    </collision>
    <inertial>
      <mass value="0.10048"/>
      <origin rpy="0 -0 0" xyz="0.0314882 -0.00644999 0.00140644"/>
      <inertia ixx="1.432e-05" ixy="4.7e-07" ixz="5.4e-07" iyy="2.66e-05" iyz="-7.1e-07" izz="2.697e-05"/>
    </inertial>
  </link>
  <gazebo reference="L_THUMBCM_Y_LINK">
    <mu1>0.9</mu1>
    <mu2>0.9</mu2>
  </gazebo>
  <link name="L_THUMBCM_P_LINK">
    <visual>
      <origin rpy="0 -0 0" xyz="0.045 0 0"/>
      <geometry>
        <mesh filename="package://hrpsys_ros_bridge_tutorials/models/HRP3HAND_L_meshes/L_THUMBCM_P_LINK_mesh.dae" scale="1 1 1"/>
      </geometry>
    </visual>
    <collision>
      <origin rpy="0 -0 0" xyz="0.045 0 0"/>
      <geometry>
        <mesh filename="package://hrpsys_ros_bridge_tutorials/models/HRP3HAND_L_meshes/L_THUMBCM_P_LINK_mesh.dae" scale="1 1 1"/>
      </geometry>
    </collision>
    <inertial>
      <mass value="0.0483845"/>
      <origin rpy="0 -0 0" xyz="0.00682086 -0.013234 -0.0305205"/>
      <inertia ixx="2.302e-05" ixy="-3.2e-07" ixz="-9.9e-07" iyy="2.227e-05" iyz="1.88e-06" izz="4.84e-06"/>
    </inertial>
  </link>
  <gazebo reference="L_THUMBCM_P_LINK">
    <mu1>0.9</mu1>
    <mu2>0.9</mu2>
  </gazebo>
  <joint name="L_INDEXMP_R" type="revolute">
    <parent link="LARM_LINK6"/>
    <child link="L_INDEXMP_R_LINK"/>
    <origin rpy="0 -0 0 " xyz="0 -0.0102 -0.1547"/>
    <axis xyz="-1 0 0"/>
    <limit effort="100" lower="-0.261799" upper="1.6057" velocity="0.5"/>
    <dynamics damping="0.2" friction="0"/>
  </joint>
  <transmission name="L_INDEXMP_R_trans" type="pr2_mechanism_model/SimpleTransmission">
    <actuator name="L_INDEXMP_R_motor"/>
    <joint name="L_INDEXMP_R"/>
    <mechanicalReduction>1</mechanicalReduction>
  </transmission>
  <gazebo reference="L_INDEXMP_R">
    <cfmDamping>0.4</cfmDamping>
  </gazebo>
  <joint name="L_INDEXMP_P" type="revolute">
    <parent link="L_INDEXMP_R_LINK"/>
    <child link="L_INDEXMP_P_LINK"/>
    <origin rpy="0 -0 0 " xyz="0.02 0 0"/>
    <axis xyz="0 -1 0"/>
    <limit effort="100" lower="-0" upper="1.5708" velocity="0.5"/>
    <dynamics damping="0.2" friction="0"/>
  </joint>
  <transmission name="L_INDEXMP_P_trans" type="pr2_mechanism_model/SimpleTransmission">
    <actuator name="L_INDEXMP_P_motor"/>
    <joint name="L_INDEXMP_P"/>
    <mechanicalReduction>1</mechanicalReduction>
  </transmission>
  <gazebo reference="L_INDEXMP_P">
    <cfmDamping>0.4</cfmDamping>
  </gazebo>
  <joint name="L_INDEXPIP_R" type="revolute">
    <parent link="L_INDEXMP_P_LINK"/>
    <child link="L_INDEXPIP_R_LINK"/>
    <origin rpy="0 -0 0 " xyz="0 -0.01125 -0.055"/>
    <axis xyz="-1 0 0"/>
    <limit effort="100" lower="-0.698132" upper="2.00713" velocity="0.5"/>
    <dynamics damping="0.2" friction="0"/>
  </joint>
  <transmission name="L_INDEXPIP_R_trans" type="pr2_mechanism_model/SimpleTransmission">
    <actuator name="L_INDEXPIP_R_motor"/>
    <joint name="L_INDEXPIP_R"/>
    <mechanicalReduction>1</mechanicalReduction>
  </transmission>
  <gazebo reference="L_INDEXPIP_R">
    <cfmDamping>0.4</cfmDamping>
  </gazebo>
  <joint name="L_MIDDLEPIP_R" type="revolute">
    <parent link="LARM_LINK6"/>
    <child link="L_MIDDLEPIP_R_LINK"/>
    <origin rpy="0 -0 0 " xyz="0 -0.02145 -0.2097"/>
    <axis xyz="-1 0 0"/>
    <limit effort="100" lower="-0.698132" upper="2.00713" velocity="0.5"/>
    <dynamics damping="0.2" friction="0"/>
  </joint>
  <transmission name="L_MIDDLEPIP_R_trans" type="pr2_mechanism_model/SimpleTransmission">
    <actuator name="L_MIDDLEPIP_R_motor"/>
    <joint name="L_MIDDLEPIP_R"/>
    <mechanicalReduction>1</mechanicalReduction>
  </transmission>
  <gazebo reference="L_MIDDLEPIP_R">
    <cfmDamping>0.4</cfmDamping>
  </gazebo>
  <joint name="L_THUMBCM_Y" type="revolute">
    <parent link="LARM_LINK6"/>
    <child link="L_THUMBCM_Y_LINK"/>
    <origin rpy="0 -0 0 " xyz="0 -0.0102 -0.1292"/>
    <axis xyz="0 0 -1"/>
    <limit effort="100" lower="-0.261799" upper="1.6057" velocity="0.5"/>
    <dynamics damping="0.2" friction="0"/>
  </joint>
  <transmission name="L_THUMBCM_Y_trans" type="pr2_mechanism_model/SimpleTransmission">
    <actuator name="L_THUMBCM_Y_motor"/>
    <joint name="L_THUMBCM_Y"/>
    <mechanicalReduction>1</mechanicalReduction>
  </transmission>
  <gazebo reference="L_THUMBCM_Y">
    <cfmDamping>0.4</cfmDamping>
  </gazebo>
  <joint name="L_THUMBCM_P" type="revolute">
    <parent link="L_THUMBCM_Y_LINK"/>
    <child link="L_THUMBCM_P_LINK"/>
    <origin rpy="0 -0 0 " xyz="0.045 0 0"/>
    <axis xyz="0 -1 0"/>
    <limit effort="100" lower="-0.523599" upper="1.6057" velocity="0.5"/>
    <dynamics damping="0.2" friction="0"/>
  </joint>
  <transmission name="L_THUMBCM_P_trans" type="pr2_mechanism_model/SimpleTransmission">
    <actuator name="L_THUMBCM_P_motor"/>
    <joint name="L_THUMBCM_P"/>
    <mechanicalReduction>1</mechanicalReduction>
  </transmission>
  <gazebo reference="L_THUMBCM_P">
    <cfmDamping>0.4</cfmDamping>
  </gazebo>
  <link name="RARM_LINK6">
    <visual>
      <origin rpy="0 -0 0" xyz="0 0 0"/>
      <geometry>
        <mesh filename="package://hrpsys_ros_bridge_tutorials/models/HRP3HAND_R_meshes/RARM_LINK6_mesh.dae" scale="1 1 1"/>
      </geometry>
    </visual>
    <collision>
      <origin rpy="0 -0 0" xyz="0 0 0"/>
      <geometry>
        <mesh filename="package://hrpsys_ros_bridge_tutorials/models/HRP3HAND_R_meshes/RARM_LINK6_mesh.dae" scale="1 1 1"/>
      </geometry>
    </collision>
    <inertial>
      <mass value="1.33256"/>
      <origin rpy="0 -0 0" xyz="0.00067085 -0.00738842 -0.085722"/>
      <inertia ixx="0.00227076" ixy="-6.3e-07" ixz="3.217e-05" iyy="0.00214173" iyz="3.72e-06" izz="0.00067255"/>
    </inertial>
  </link>
  <gazebo reference="RARM_LINK6">
    <mu1>0.9</mu1>
    <mu2>0.9</mu2>
  </gazebo>
  <link name="R_INDEXMP_R_LINK">
    <visual>
      <origin rpy="0 -0 0" xyz="0 0.0102 -0.1547"/>
      <geometry>
        <mesh filename="package://hrpsys_ros_bridge_tutorials/models/HRP3HAND_R_meshes/R_INDEXMP_R_LINK_mesh.dae" scale="1 1 1"/>
      </geometry>
    </visual>
    <collision>
      <origin rpy="0 -0 0" xyz="0 0.0102 -0.1547"/>
      <geometry>
        <mesh filename="package://hrpsys_ros_bridge_tutorials/models/HRP3HAND_R_meshes/R_INDEXMP_R_LINK_mesh.dae" scale="1 1 1"/>
      </geometry>
    </collision>
    <inertial>
      <mass value="0.0158629"/>
      <origin rpy="0 -0 0" xyz="0.00509194 -0.00581104 6.273e-05"/>
      <inertia ixx="9.9e-07" ixy="7.6e-07" ixz="-7.94093e-23" iyy="1.61e-06" iyz="1e-08" izz="2.16e-06"/>
    </inertial>
  </link>
  <gazebo reference="R_INDEXMP_R_LINK">
    <mu1>0.9</mu1>
    <mu2>0.9</mu2>
  </gazebo>
  <link name="R_INDEXMP_P_LINK">
    <visual>
      <origin rpy="0 -0 0" xyz="0.02 0 0"/>
      <geometry>
        <mesh filename="package://hrpsys_ros_bridge_tutorials/models/HRP3HAND_R_meshes/R_INDEXMP_P_LINK_mesh.dae" scale="1 1 1"/>
      </geometry>
    </visual>
    <collision>
      <origin rpy="0 -0 0" xyz="0.02 0 0"/>
      <geometry>
        <mesh filename="package://hrpsys_ros_bridge_tutorials/models/HRP3HAND_R_meshes/R_INDEXMP_P_LINK_mesh.dae" scale="1 1 1"/>
      </geometry>
    </collision>
    <inertial>
      <mass value="0.106231"/>
      <origin rpy="0 -0 0" xyz="-0.00078463 0.00129762 -0.0281757"/>
      <inertia ixx="5.089e-05" ixy="6.2e-07" ixz="-1.87e-06" iyy="4.739e-05" iyz="1.05e-05" izz="1.005e-05"/>
    </inertial>
  </link>
  <gazebo reference="R_INDEXMP_P_LINK">
    <mu1>0.9</mu1>
    <mu2>0.9</mu2>
  </gazebo>
  <link name="R_INDEXPIP_R_LINK">
    <visual>
      <origin rpy="0 -0 0" xyz="0 0.01125 -0.055"/>
      <geometry>
        <mesh filename="package://hrpsys_ros_bridge_tutorials/models/HRP3HAND_R_meshes/R_INDEXPIP_R_LINK_mesh.dae" scale="1 1 1"/>
      </geometry>
    </visual>
    <collision>
      <origin rpy="0 -0 0" xyz="0 0.01125 -0.055"/>
      <geometry>
        <mesh filename="package://hrpsys_ros_bridge_tutorials/models/HRP3HAND_R_meshes/R_INDEXPIP_R_LINK_mesh.dae" scale="1 1 1"/>
      </geometry>
    </collision>
    <inertial>
      <mass value="0.0215832"/>
      <origin rpy="0 -0 0" xyz="0.0210676 0.0134797 -0.0204042"/>
      <inertia ixx="4.06e-06" ixy="2.2e-07" ixz="-2.9e-07" iyy="2.34e-06" iyz="1.55e-06" izz="3.05e-06"/>
    </inertial>
  </link>
  <gazebo reference="R_INDEXPIP_R_LINK">
    <mu1>0.9</mu1>
    <mu2>0.9</mu2>
  </gazebo>
  <link name="R_MIDDLEPIP_R_LINK">
    <visual>
      <origin rpy="0 -0 0" xyz="0 0.02145 -0.2097"/>
      <geometry>
        <mesh filename="package://hrpsys_ros_bridge_tutorials/models/HRP3HAND_R_meshes/R_MIDDLEPIP_R_LINK_mesh.dae" scale="1 1 1"/>
      </geometry>
    </visual>
    <collision>
      <origin rpy="0 -0 0" xyz="0 0.02145 -0.2097"/>
      <geometry>
        <mesh filename="package://hrpsys_ros_bridge_tutorials/models/HRP3HAND_R_meshes/R_MIDDLEPIP_R_LINK_mesh.dae" scale="1 1 1"/>
      </geometry>
    </collision>
    <inertial>
      <mass value="0.0367086"/>
      <origin rpy="0 -0 0" xyz="-0.0171953 0.0140037 -0.0195553"/>
      <inertia ixx="9.9e-06" ixy="6.2e-07" ixz="-8.7e-07" iyy="1.003e-05" iyz="3.95e-06" izz="1.043e-05"/>
    </inertial>
  </link>
  <gazebo reference="R_MIDDLEPIP_R_LINK">
    <mu1>0.9</mu1>
    <mu2>0.9</mu2>
  </gazebo>
  <link name="R_THUMBCM_Y_LINK">
    <visual>
      <origin rpy="0 -0 0" xyz="0 0.0102 -0.1292"/>
      <geometry>
        <mesh filename="package://hrpsys_ros_bridge_tutorials/models/HRP3HAND_R_meshes/R_THUMBCM_Y_LINK_mesh.dae" scale="1 1 1"/>
      </geometry>
    </visual>
    <collision>
      <origin rpy="0 -0 0" xyz="0 0.0102 -0.1292"/>
      <geometry>
        <mesh filename="package://hrpsys_ros_bridge_tutorials/models/HRP3HAND_R_meshes/R_THUMBCM_Y_LINK_mesh.dae" scale="1 1 1"/>
      </geometry>
    </collision>
    <inertial>
      <mass value="0.10048"/>
      <origin rpy="0 -0 0" xyz="0.0314882 0.00644999 0.00140644"/>
      <inertia ixx="1.432e-05" ixy="-4.7e-07" ixz="5.4e-07" iyy="2.66e-05" iyz="7.1e-07" izz="2.697e-05"/>
    </inertial>
  </link>
  <gazebo reference="R_THUMBCM_Y_LINK">
    <mu1>0.9</mu1>
    <mu2>0.9</mu2>
  </gazebo>
  <link name="R_THUMBCM_P_LINK">
    <visual>
      <origin rpy="0 -0 0" xyz="0.045 0 0"/>
      <geometry>
        <mesh filename="package://hrpsys_ros_bridge_tutorials/models/HRP3HAND_R_meshes/R_THUMBCM_P_LINK_mesh.dae" scale="1 1 1"/>
      </geometry>
    </visual>
    <collision>
      <origin rpy="0 -0 0" xyz="0.045 0 0"/>
      <geometry>
        <mesh filename="package://hrpsys_ros_bridge_tutorials/models/HRP3HAND_R_meshes/R_THUMBCM_P_LINK_mesh.dae" scale="1 1 1"/>
      </geometry>
    </collision>
    <inertial>
      <mass value="0.0483845"/>
      <origin rpy="0 -0 0" xyz="0.00682086 0.013234 -0.0305205"/>
      <inertia ixx="2.302e-05" ixy="3.2e-07" ixz="-9.9e-07" iyy="2.227e-05" iyz="-1.88e-06" izz="4.84e-06"/>
    </inertial>
  </link>
  <gazebo reference="R_THUMBCM_P_LINK">
    <mu1>0.9</mu1>
    <mu2>0.9</mu2>
  </gazebo>
  <joint name="R_INDEXMP_R" type="revolute">
    <parent link="RARM_LINK6"/>
    <child link="R_INDEXMP_R_LINK"/>
    <origin rpy="0 -0 0 " xyz="0 0.0102 -0.1547"/>
    <axis xyz="1 0 0"/>
    <limit effort="100" lower="-0.261799" upper="1.6057" velocity="0.5"/>
    <dynamics damping="0.2" friction="0"/>
  </joint>
  <transmission name="R_INDEXMP_R_trans" type="pr2_mechanism_model/SimpleTransmission">
    <actuator name="R_INDEXMP_R_motor"/>
    <joint name="R_INDEXMP_R"/>
    <mechanicalReduction>1</mechanicalReduction>
  </transmission>
  <gazebo reference="R_INDEXMP_R">
    <cfmDamping>0.4</cfmDamping>
  </gazebo>
  <joint name="R_INDEXMP_P" type="revolute">
    <parent link="R_INDEXMP_R_LINK"/>
    <child link="R_INDEXMP_P_LINK"/>
    <origin rpy="0 -0 0 " xyz="0.02 0 0"/>
    <axis xyz="0 -1 0"/>
    <limit effort="100" lower="-0" upper="1.5708" velocity="0.5"/>
    <dynamics damping="0.2" friction="0"/>
  </joint>
  <transmission name="R_INDEXMP_P_trans" type="pr2_mechanism_model/SimpleTransmission">
    <actuator name="R_INDEXMP_P_motor"/>
    <joint name="R_INDEXMP_P"/>
    <mechanicalReduction>1</mechanicalReduction>
  </transmission>
  <gazebo reference="R_INDEXMP_P">
    <cfmDamping>0.4</cfmDamping>
  </gazebo>
  <joint name="R_INDEXPIP_R" type="revolute">
    <parent link="R_INDEXMP_P_LINK"/>
    <child link="R_INDEXPIP_R_LINK"/>
    <origin rpy="0 -0 0 " xyz="0 0.01125 -0.055"/>
    <axis xyz="1 0 0"/>
    <limit effort="100" lower="-0.698132" upper="2.00713" velocity="0.5"/>
    <dynamics damping="0.2" friction="0"/>
  </joint>
  <transmission name="R_INDEXPIP_R_trans" type="pr2_mechanism_model/SimpleTransmission">
    <actuator name="R_INDEXPIP_R_motor"/>
    <joint name="R_INDEXPIP_R"/>
    <mechanicalReduction>1</mechanicalReduction>
  </transmission>
  <gazebo reference="R_INDEXPIP_R">
    <cfmDamping>0.4</cfmDamping>
  </gazebo>
  <joint name="R_MIDDLEPIP_R" type="revolute">
    <parent link="RARM_LINK6"/>
    <child link="R_MIDDLEPIP_R_LINK"/>
    <origin rpy="0 -0 0 " xyz="0 0.02145 -0.2097"/>
    <axis xyz="1 0 0"/>
    <limit effort="100" lower="-0.698132" upper="2.00713" velocity="0.5"/>
    <dynamics damping="0.2" friction="0"/>
  </joint>
  <transmission name="R_MIDDLEPIP_R_trans" type="pr2_mechanism_model/SimpleTransmission">
    <actuator name="R_MIDDLEPIP_R_motor"/>
    <joint name="R_MIDDLEPIP_R"/>
    <mechanicalReduction>1</mechanicalReduction>
  </transmission>
  <gazebo reference="R_MIDDLEPIP_R">
    <cfmDamping>0.4</cfmDamping>
  </gazebo>
  <joint name="R_THUMBCM_Y" type="revolute">
    <parent link="RARM_LINK6"/>
    <child link="R_THUMBCM_Y_LINK"/>
    <origin rpy="0 -0 0 " xyz="0 0.0102 -0.1292"/>
    <axis xyz="0 0 1"/>
    <limit effort="100" lower="-0.261799" upper="1.6057" velocity="0.5"/>
    <dynamics damping="0.2" friction="0"/>
  </joint>
  <transmission name="R_THUMBCM_Y_trans" type="pr2_mechanism_model/SimpleTransmission">
    <actuator name="R_THUMBCM_Y_motor"/>
    <joint name="R_THUMBCM_Y"/>
    <mechanicalReduction>1</mechanicalReduction>
  </transmission>
  <gazebo reference="R_THUMBCM_Y">
    <cfmDamping>0.4</cfmDamping>
  </gazebo>
  <joint name="R_THUMBCM_P" type="revolute">
    <parent link="R_THUMBCM_Y_LINK"/>
    <child link="R_THUMBCM_P_LINK"/>
    <origin rpy="0 -0 0 " xyz="0.045 0 0"/>
    <axis xyz="0 -1 0"/>
    <limit effort="100" lower="-0.523599" upper="1.6057" velocity="0.5"/>
    <dynamics damping="0.2" friction="0"/>
  </joint>
  <transmission name="R_THUMBCM_P_trans" type="pr2_mechanism_model/SimpleTransmission">
    <actuator name="R_THUMBCM_P_motor"/>
    <joint name="R_THUMBCM_P"/>
    <mechanicalReduction>1</mechanicalReduction>
  </transmission>
  <gazebo reference="R_THUMBCM_P">
    <cfmDamping>0.4</cfmDamping>
  </gazebo>
  <link name="head_root"/>
  <joint name="head_root_joint" type="fixed">
    <parent link="head_root"/>
    <child link="head"/>
  </joint>
  <link name="head">
    <inertial>
      <origin rpy="0 0 0" xyz="-0.075493 3.3383E-05 0.02774"/>
      <mass value="1.4199"/>
      <inertia ixx="0.0039688" ixy="-1.5797E-06" ixz="-0.00089293" iyy="0.0041178" iyz="-6.8415E-07" izz="0.0035243"/>
    </inertial>
    <visual>
      <origin rpy="0 0 0" xyz="0 0  0"/>
      <geometry>
        <mesh filename="package://multisense_description/meshes/head.dae"/>
      </geometry>
      <material name="">
        <color rgba="0.9098 0.44314 0.031373 1"/>
      </material>
    </visual>
    <collision>
      <origin rpy="0 0 0" xyz="-0.0503 0 -0.00195"/>
      <geometry>
        <box size="0.1311 0.12 0.0591"/>
      </geometry>
    </collision>
  </link>
  <joint name="left_camera_optical_joint" type="continuous">
    <parent link="left_camera_optical_frame"/>
    <child link="motor"/>
  </joint>
  <link name="motor"/>
  <link name="spindle"/>
  <joint name="motor_joint" type="continuous">
    <parent link="motor"/>
    <child link="spindle"/>
    <axis xyz="0 0 1"/>
  </joint>
  <joint name="spindle_joint" type="continuous">
    <parent link="spindle"/>
    <child link="hokuyo_link"/>
  </joint>
  <link name="hokuyo_link">
    <inertial>
      <origin rpy="0 0 0" xyz="0.012428 0.0004084 -0.0041835"/>
      <mass value="0.057664"/>
      <inertia ixx="3.7174E-05" ixy="4.9927E-08" ixz="1.1015E-05" iyy="4.2412E-05" iyz="-9.8165E-09" izz="4.167E-05"/>
    </inertial>
    <visual>
      <origin rpy="-1.9179632679 -1.57079632679 0" xyz="-.03 -.1 0"/>
      <geometry>
        <mesh filename="package://multisense_description/meshes/head_camera.dae"/>
      </geometry>
      <material name="">
        <color rgba="0.72941 0.35686 0.023529 1"/>
      </material>
    </visual>
    <collision>
      <origin rpy="0 0 0" xyz="0.03 0 0.0235"/>
      <geometry>
        <cylinder length="0.047" radius="0.024425"/>
      </geometry>
    </collision>
  </link>
  <link name="head_hokuyo_frame"/>
  <joint name="head_hokuyo_frame_joint" type="fixed">
    <!--
     This transform accounts for the fact ROS expects laser data in the x forward,
     y left, z up frame and the calibraton has the data in x left, y up, z forward.
     Thus a roll of -90 * a pitch of -90 will make the appropriate transform. Note
     Roll and pitch are both with respect to the origional x left, y up, z forward frame
     -->
    <origin rpy="-1.57079632679 -1.57079632679 0.0" xyz="0 0 0"/>
    <parent link="hokuyo_link"/>
    <child link="head_hokuyo_frame"/>
  </joint>
  <joint name="left_camera_frame_joint" type="fixed">
    <!-- optical frame collocated with tilting DOF -->
    <origin xyz="0.0 0.035 -0.002"/>
    <parent link="head"/>
    <child link="left_camera_frame"/>
  </joint>
  <link name="left_camera_frame">
    <inertial>
      <mass value="0.1"/>
      <origin xyz="0 0 0"/>
      <inertia ixx="0.001" ixy="0.0" ixz="0.0" iyy="0.001" iyz="0.0" izz="0.001"/>
    </inertial>
  </link>
  <joint name="left_camera_optical_frame_joint" type="fixed">
    <origin rpy="-1.57079632679 0.0 -1.57079632679" xyz="0 0 0"/>
    <parent link="left_camera_frame"/>
    <child link="left_camera_optical_frame"/>
  </joint>
  <link name="left_camera_optical_frame"/>
  <joint name="right_camera_frame_joint" type="fixed">
    <origin xyz="0.0 -0.035 -0.002"/>
    <parent link="head"/>
    <child link="right_camera_frame"/>
  </joint>
  <link name="right_camera_frame">
    <inertial>
      <mass value="0.1"/>
      <origin xyz="0 0 0"/>
      <inertia ixx="0.001" ixy="0.0" ixz="0.0" iyy="0.001" iyz="0.0" izz="0.001"/>
    </inertial>
  </link>
  <joint name="right_camera_optical_frame_joint" type="fixed">
    <origin rpy="-1.5708 0.0 -1.5708" xyz="0 0 0"/>
    <parent link="right_camera_frame"/>
    <child link="right_camera_optical_frame"/>
  </joint>
  <link name="right_camera_optical_frame"/>
  <joint name="center_top_led_frame_joint" type="fixed">
    <origin xyz="0.01125 0.0 0.0105"/>
    <parent link="head"/>
    <child link="center_top_led_frame"/>
  </joint>
  <link name="center_top_led_frame">
    <inertial>
      <mass value="0.1"/>
      <origin xyz="0 0 0"/>
      <inertia ixx="0.001" ixy="0.0" ixz="0.0" iyy="0.001" iyz="0.0" izz="0.001"/>
    </inertial>
  </link>
  <joint name="center_bottom_led_frame_joint" type="fixed">
    <origin xyz="0.01125 0.0 -0.0155"/>
    <parent link="head"/>
    <child link="center_bottom_led_frame"/>
  </joint>
  <link name="center_bottom_led_frame">
    <inertial>
      <mass value="0.1"/>
      <origin xyz="0 0 0"/>
      <inertia ixx="0.001" ixy="0.0" ixz="0.0" iyy="0.001" iyz="0.0" izz="0.001"/>
    </inertial>
  </link>
  <joint name="left_led_frame_joint" type="fixed">
    <origin rpy="0 -0.15 0.53" xyz="-0.01443 0.07452 0.050346"/>
    <parent link="head"/>
    <child link="left_led_frame"/>
  </joint>
  <link name="left_led_frame">
    <inertial>
      <mass value="0.1"/>
      <origin xyz="0 0 0"/>
      <inertia ixx="0.001" ixy="0.0" ixz="0.0" iyy="0.001" iyz="0.0" izz="0.001"/>
    </inertial>
  </link>
  <joint name="right_led_frame_joint" type="fixed">
    <origin rpy="0 -0.15 -0.53" xyz="-0.01443 -0.07452 0.050346"/>
    <parent link="head"/>
    <child link="right_led_frame"/>
  </joint>
  <link name="right_led_frame">
    <inertial>
      <mass value="0.1"/>
      <origin xyz="0 0 0"/>
      <inertia ixx="0.001" ixy="0.0" ixz="0.0" iyy="0.001" iyz="0.0" izz="0.001"/>
    </inertial>
  </link>
  <link name="accel"/>
  <joint name="accel_joint" type="fixed">
    <origin rpy="0 1.5707 0" xyz="-.0475 .0302 -.00275"/>
    <parent link="head_root"/>
    <child link="accel"/>
  </joint>
  <link name="mag"/>
  <joint name="mag_joint" type="fixed">
    <origin rpy="0 1.5707 0" xyz="-.0475 .0302 -.00275"/>
    <parent link="head_root"/>
    <child link="mag"/>
  </joint>
  <link name="gyro"/>
  <joint name="gyro_joint" type="fixed">
    <origin rpy="1.5707 3.14159 1.5707 " xyz="-.0476 .0388 -.00075"/>
    <parent link="head_root"/>
    <child link="gyro"/>
  </joint>
  <joint name="hrp2_to_multisense" type="fixed">
    <parent link="HEAD_LINK1"/>
    <!--child  link="head" /-->
    <!-- for drcsim / multisense_sl_description -->
    <child link="head_root"/>
    <!-- for multisense / multisense_description -->
    <!--origin xyz="0.07595 0 0.19825" rpy="0 0 0"/-->
    <origin rpy="0 0 0" xyz="0.0 0.0 0.1"/>
    <!-- calibrated 2015.01.21-->
  </joint>
</robot>

